Workbook
Name Hari_Libur: Libur!$A$2:$A$200

Sheet SCurve
B2: Project Name | C2: Auto Bandwidth on Demand
B3: Client | C3: PT Aplikanusa Lintasarta
B4: Project Manager | C4: Lesy Nugraheny
B5: Project Due Date | C5: 46262
B6: PO Due Date | C6: 46265
B7: W1 Project Date | C7: 46156
B8: Project Status Date | C8: 46156
B10: Target Linear | C10: Progress | D10: Deviation
B11: =J62 -> 0.051428571 | C11: =L62 -> 0.055 | D11: =C11-B11 -> 0.0035714286
P16: 46149 | Q16: =P17+1 -> 46157 | R16: =Q17+1 -> 46164 | S16: =R17+1 -> 46171 | T16: =S17+1 -> 46178 | U16: =T17+1 -> 46185 | V16: =U17+1 -> 46192 | W16: =V17+1 -> 46199 | X16: =W17+1 -> 46206 | ... BK16: =BJ17+1 -> 46479
P17: 46156 | Q17: =P17+7 -> 46163 | R17: =Q17+7 -> 46170 | S17: =R17+7 -> 46177 | T17: =S17+7 -> 46184 | U17: =T17+7 -> 46191 | V17: =U17+7 -> 46198 | W17: =V17+7 -> 46205 | X17: =W17+7 -> 46212 | ... BK17: =BJ17+7 -> 46485
A18: No | B18: Task | C18: Bobot | D18: Start Date | E18: Finish Date | F18: Bobot | G18: Σ Minggu | H18: Duration | I18: Linear Target | K18: Actual Progress | M18: Deviation | N18: Bobot | O18: Σ Minggu | P18: Week-01 | Q18: Week-02 | R18: Week-03 | S18: Week-04 | T18: Week-05 | U18: Week-06 | V18: Week-07 | W18: Week-08 | X18: Week-09 | Y18: Week-10 | Z18: Week-11 | AA18: Week-12 | AB18: Week-13 | AC18: Week-14 | AD18: Week-15 | AE18: Week-16 | AF18: Week-17 | AG18: Week-18 | AH18: Week-19 | AI18: Week-20 | AJ18: Week-21 | AK18: Week-22 | AL18: Week-23 | AM18: Week-24 | AN18: Week-25 | AO18: Week-26 | AP18: Week-27 | AQ18: Week-28 | AR18: Week-29 | AS18: Week-30 | AT18: Week-31 | AU18: Week-32 | AV18: Week-33 | AW18: Week-34 | AX18: Week-35 | AY18: Week-36 | AZ18: Week-37 | BA18: Week-38 | BB18: Week-39 | BC18: Week-40 | BD18: Week-41 | BE18: Week-42 | BF18: Week-43 | BG18: Week-44 | BH18: Week-45 | BI18: Week-46 | BJ18: Week-47 | BK18: Week-48
I19: Weight (%) | J19: % | K19: Progress | L19: % | M19: %
A20: I | B20: INITIATION & PLANNING | C20: =SUM(C21:C21) -> 0.01 | D20: =MIN(D21:D21) -> 46149 | E20: =MAX(E21:E21) -> 46149 | H20: =NETWORKDAYS(D20,E20,Hari_Libur) -> 1 | I20: =IF(C20=0,0,J20/C20) -> 1 | J20: =SUM(J21:J21) -> 0.01 | K20: =IF(C20=0,0,L20/C20) -> 1 | L20: =SUM(L21:L21) -> 0.01 | M20: =SUM(M21:M21) -> 0
B21: Kick Off Meeting | C21: 0.01 | D21: 46149 | E21: 46149 | F21: =C21 -> 0.01 | G21: =SUM(P21:AZ21) -> 0.01 | H21: =NETWORKDAYS(D21,E21,Hari_Libur) -> 1 | I21: =IF($C$8>=E21,1,IF($C$8<D21,0,IF(NETWORKDAYS(D21,E21,Hari_Libur)=0,0,NETWORKDAYS(D21,$C$8,Hari_Libur)/NETWORKDAYS(D21,E21,Hari_Libur)))) -> 1 | J21: =I21*F21 -> 0.01 | K21: 1 | L21: =C21*K21 -> 0.01 | M21: =L21-J21 -> 0 | N21: =C21 -> 0.01 | O21: =SUM(P21:BK21) -> 0.01 | P21: =IF(AND($D21<=P$17,$E21>=P$16),$C21*NETWORKDAYS(MAX($D21,P$16),MIN($E21,P$17),Hari_Libur)/NETWORKDAYS($D21,$E21,Hari_Libur),0) -> 0.01 | Q21: =IF(AND($D21<=Q$17,$E21>=Q$16),$C21*NETWORKDAYS(MAX($D21,Q$16),MIN($E21,Q$17),Hari_Libur)/NETWORKDAYS($D21,$E21,Hari_Libur),0) -> 0 | R21: =IF(AND($D21<=R$17,$E21>=R$16),$C21*NETWORKDAYS(MAX($D21,R$16),MIN($E21,R$17),Hari_Libur)/NETWORKDAYS($D21,$E21,Hari_Libur),0) -> 0 | S21: =IF(AND($D21<=S$17,$E21>=S$16),$C21*NETWORKDAYS(MAX($D21,S$16),MIN($E21,S$17),Hari_Libur)/NETWORKDAYS($D21,$E21,Hari_Libur),0) -> 0 | T21: =IF(AND($D21<=T$17,$E21>=T$16),$C21*NETWORKDAYS(MAX($D21,T$16),MIN($E21,T$17),Hari_Libur)/NETWORKDAYS($D21,$E21,Hari_Libur),0) -> 0 | U21: =IF(AND($D21<=U$17,$E21>=U$16),$C21*NETWORKDAYS(MAX($D21,U$16),MIN($E21,U$17),Hari_Libur)/NETWORKDAYS($D21,$E21,Hari_Libur),0) -> 0 | V21: =IF(AND($D21<=V$17,$E21>=V$16),$C21*NETWORKDAYS(MAX($D21,V$16),MIN($E21,V$17),Hari_Libur)/NETWORKDAYS($D21,$E21,Hari_Libur),0) -> 0 | W21: =IF(AND($D21<=W$17,$E21>=W$16),$C21*NETWORKDAYS(MAX($D21,W$16),MIN($E21,W$17),Hari_Libur)/NETWORKDAYS($D21,$E21,Hari_Libur),0) -> 0 | ... BK21: =IF(AND($D21<=BK$17,$E21>=BK$16),$C21*NETWORKDAYS(MAX($D21,BK$16),MIN($E21,BK$17),Hari_Libur)/NETWORKDAYS($D21,$E21,Hari_Libur),0) -> 0
P22: =IF(AND($D22<=P$17,$E22>=P$16),$C22*NETWORKDAYS(MAX($D22,P$16),MIN($E22,P$17),Libur!$A$2:$A$38)/NETWORKDAYS($D22,$E22,Libur!$A$2:$A$38),0) -> 0 | Q22: =IF(AND($D22<=Q$17,$E22>=Q$16),$C22*NETWORKDAYS(MAX($D22,Q$16),MIN($E22,Q$17),Libur!$A$2:$A$38)/NETWORKDAYS($D22,$E22,Libur!$A$2:$A$38),0) -> 0 | R22: =IF(AND($D22<=R$17,$E22>=R$16),$C22*NETWORKDAYS(MAX($D22,R$16),MIN($E22,R$17),Libur!$A$2:$A$38)/NETWORKDAYS($D22,$E22,Libur!$A$2:$A$38),0) -> 0 | S22: =IF(AND($D22<=S$17,$E22>=S$16),$C22*NETWORKDAYS(MAX($D22,S$16),MIN($E22,S$17),Libur!$A$2:$A$38)/NETWORKDAYS($D22,$E22,Libur!$A$2:$A$38),0) -> 0 | T22: =IF(AND($D22<=T$17,$E22>=T$16),$C22*NETWORKDAYS(MAX($D22,T$16),MIN($E22,T$17),Libur!$A$2:$A$38)/NETWORKDAYS($D22,$E22,Libur!$A$2:$A$38),0) -> 0 | U22: =IF(AND($D22<=U$17,$E22>=U$16),$C22*NETWORKDAYS(MAX($D22,U$16),MIN($E22,U$17),Libur!$A$2:$A$38)/NETWORKDAYS($D22,$E22,Libur!$A$2:$A$38),0) -> 0 | V22: =IF(AND($D22<=V$17,$E22>=V$16),$C22*NETWORKDAYS(MAX($D22,V$16),MIN($E22,V$17),Libur!$A$2:$A$38)/NETWORKDAYS($D22,$E22,Libur!$A$2:$A$38),0) -> 0 | W22: =IF(AND($D22<=W$17,$E22>=W$16),$C22*NETWORKDAYS(MAX($D22,W$16),MIN($E22,W$17),Libur!$A$2:$A$38)/NETWORKDAYS($D22,$E22,Libur!$A$2:$A$38),0) -> 0 | ... BK22: =IF(AND($D22<=BK$17,$E22>=BK$16),$C22*NETWORKDAYS(MAX($D22,BK$16),MIN($E22,BK$17),Libur!$A$2:$A$38)/NETWORKDAYS($D22,$E22,Libur!$A$2:$A$38),0) -> 0
P23: =IF(AND($D23<=P$17,$E23>=P$16),$C23*NETWORKDAYS(MAX($D23,P$16),MIN($E23,P$17),Libur!$A$2:$A$38)/NETWORKDAYS($D23,$E23,Libur!$A$2:$A$38),0) -> 0 | Q23: =IF(AND($D23<=Q$17,$E23>=Q$16),$C23*NETWORKDAYS(MAX($D23,Q$16),MIN($E23,Q$17),Libur!$A$2:$A$38)/NETWORKDAYS($D23,$E23,Libur!$A$2:$A$38),0) -> 0 | R23: =IF(AND($D23<=R$17,$E23>=R$16),$C23*NETWORKDAYS(MAX($D23,R$16),MIN($E23,R$17),Libur!$A$2:$A$38)/NETWORKDAYS($D23,$E23,Libur!$A$2:$A$38),0) -> 0 | S23: =IF(AND($D23<=S$17,$E23>=S$16),$C23*NETWORKDAYS(MAX($D23,S$16),MIN($E23,S$17),Libur!$A$2:$A$38)/NETWORKDAYS($D23,$E23,Libur!$A$2:$A$38),0) -> 0 | T23: =IF(AND($D23<=T$17,$E23>=T$16),$C23*NETWORKDAYS(MAX($D23,T$16),MIN($E23,T$17),Libur!$A$2:$A$38)/NETWORKDAYS($D23,$E23,Libur!$A$2:$A$38),0) -> 0 | U23: =IF(AND($D23<=U$17,$E23>=U$16),$C23*NETWORKDAYS(MAX($D23,U$16),MIN($E23,U$17),Libur!$A$2:$A$38)/NETWORKDAYS($D23,$E23,Libur!$A$2:$A$38),0) -> 0 | V23: =IF(AND($D23<=V$17,$E23>=V$16),$C23*NETWORKDAYS(MAX($D23,V$16),MIN($E23,V$17),Libur!$A$2:$A$38)/NETWORKDAYS($D23,$E23,Libur!$A$2:$A$38),0) -> 0 | W23: =IF(AND($D23<=W$17,$E23>=W$16),$C23*NETWORKDAYS(MAX($D23,W$16),MIN($E23,W$17),Libur!$A$2:$A$38)/NETWORKDAYS($D23,$E23,Libur!$A$2:$A$38),0) -> 0 | ... BK23: =IF(AND($D23<=BK$17,$E23>=BK$16),$C23*NETWORKDAYS(MAX($D23,BK$16),MIN($E23,BK$17),Libur!$A$2:$A$38)/NETWORKDAYS($D23,$E23,Libur!$A$2:$A$38),0) -> 0
A24: II | B24: PREPARATION | C24: =SUM(C25:C26) -> 0.04 | D24: =MIN(D25:D26) -> 46151 | E24: =MAX(E25:E26) -> 46161 | H24: =NETWORKDAYS(D24,E24,Hari_Libur) -> 5 | I24: =IF(C24=0,0,J24/C24) -> 0.5 | J24: =SUM(J25:J26) -> 0.02 | K24: =IF(C24=0,0,L24/C24) -> 0.5 | L24: =SUM(L25:L26) -> 0.02 | M24: =SUM(M25:M26) -> 0
B25: Sync Repo with the Staging Repo | C25: 0.02 | D25: 46151 | E25: 46155 | F25: =C25 -> 0.02 | G25: =SUM(P25:AZ25) -> 0.02 | H25: =NETWORKDAYS(D25,E25,Hari_Libur) -> 3 | I25: =IF($C$8>=E25,1,IF($C$8<D25,0,IF(NETWORKDAYS(D25,E25,Hari_Libur)=0,0,NETWORKDAYS(D25,$C$8,Hari_Libur)/NETWORKDAYS(D25,E25,Hari_Libur)))) -> 1 | J25: =I25*F25 -> 0.02 | K25: 1 | L25: =C25*K25 -> 0.02 | M25: =L25-J25 -> 0 | N25: =C25 -> 0.02 | O25: =SUM(P25:BK25) -> 0.02 | P25: =IF(AND($D25<=P$17,$E25>=P$16),$C25*NETWORKDAYS(MAX($D25,P$16),MIN($E25,P$17),Hari_Libur)/NETWORKDAYS($D25,$E25,Hari_Libur),0) -> 0.02 | Q25: =IF(AND($D25<=Q$17,$E25>=Q$16),$C25*NETWORKDAYS(MAX($D25,Q$16),MIN($E25,Q$17),Hari_Libur)/NETWORKDAYS($D25,$E25,Hari_Libur),0) -> 0 | R25: =IF(AND($D25<=R$17,$E25>=R$16),$C25*NETWORKDAYS(MAX($D25,R$16),MIN($E25,R$17),Hari_Libur)/NETWORKDAYS($D25,$E25,Hari_Libur),0) -> 0 | S25: =IF(AND($D25<=S$17,$E25>=S$16),$C25*NETWORKDAYS(MAX($D25,S$16),MIN($E25,S$17),Hari_Libur)/NETWORKDAYS($D25,$E25,Hari_Libur),0) -> 0 | T25: =IF(AND($D25<=T$17,$E25>=T$16),$C25*NETWORKDAYS(MAX($D25,T$16),MIN($E25,T$17),Hari_Libur)/NETWORKDAYS($D25,$E25,Hari_Libur),0) -> 0 | U25: =IF(AND($D25<=U$17,$E25>=U$16),$C25*NETWORKDAYS(MAX($D25,U$16),MIN($E25,U$17),Hari_Libur)/NETWORKDAYS($D25,$E25,Hari_Libur),0) -> 0 | V25: =IF(AND($D25<=V$17,$E25>=V$16),$C25*NETWORKDAYS(MAX($D25,V$16),MIN($E25,V$17),Hari_Libur)/NETWORKDAYS($D25,$E25,Hari_Libur),0) -> 0 | W25: =IF(AND($D25<=W$17,$E25>=W$16),$C25*NETWORKDAYS(MAX($D25,W$16),MIN($E25,W$17),Hari_Libur)/NETWORKDAYS($D25,$E25,Hari_Libur),0) -> 0 | ... BK25: =IF(AND($D25<=BK$17,$E25>=BK$16),$C25*NETWORKDAYS(MAX($D25,BK$16),MIN($E25,BK$17),Hari_Libur)/NETWORKDAYS($D25,$E25,Hari_Libur),0) -> 0
B26: Environment Setup for BOWD | C26: 0.02 | D26: 46160 | E26: 46161 | F26: =C26 -> 0.02 | G26: =SUM(P26:AZ26) -> 0.02 | H26: =NETWORKDAYS(D26,E26,Hari_Libur) -> 2 | I26: =IF($C$8>=E26,1,IF($C$8<D26,0,IF(NETWORKDAYS(D26,E26,Hari_Libur)=0,0,NETWORKDAYS(D26,$C$8,Hari_Libur)/NETWORKDAYS(D26,E26,Hari_Libur)))) -> 0 | J26: =I26*F26 -> 0 | K26: 0 | L26: =C26*K26 -> 0 | M26: =L26-J26 -> 0 | N26: =C26 -> 0.02 | O26: =SUM(P26:BK26) -> 0.02 | P26: =IF(AND($D26<=P$17,$E26>=P$16),$C26*NETWORKDAYS(MAX($D26,P$16),MIN($E26,P$17),Hari_Libur)/NETWORKDAYS($D26,$E26,Hari_Libur),0) -> 0 | Q26: =IF(AND($D26<=Q$17,$E26>=Q$16),$C26*NETWORKDAYS(MAX($D26,Q$16),MIN($E26,Q$17),Hari_Libur)/NETWORKDAYS($D26,$E26,Hari_Libur),0) -> 0.02 | R26: =IF(AND($D26<=R$17,$E26>=R$16),$C26*NETWORKDAYS(MAX($D26,R$16),MIN($E26,R$17),Hari_Libur)/NETWORKDAYS($D26,$E26,Hari_Libur),0) -> 0 | S26: =IF(AND($D26<=S$17,$E26>=S$16),$C26*NETWORKDAYS(MAX($D26,S$16),MIN($E26,S$17),Hari_Libur)/NETWORKDAYS($D26,$E26,Hari_Libur),0) -> 0 | T26: =IF(AND($D26<=T$17,$E26>=T$16),$C26*NETWORKDAYS(MAX($D26,T$16),MIN($E26,T$17),Hari_Libur)/NETWORKDAYS($D26,$E26,Hari_Libur),0) -> 0 | U26: =IF(AND($D26<=U$17,$E26>=U$16),$C26*NETWORKDAYS(MAX($D26,U$16),MIN($E26,U$17),Hari_Libur)/NETWORKDAYS($D26,$E26,Hari_Libur),0) -> 0 | V26: =IF(AND($D26<=V$17,$E26>=V$16),$C26*NETWORKDAYS(MAX($D26,V$16),MIN($E26,V$17),Hari_Libur)/NETWORKDAYS($D26,$E26,Hari_Libur),0) -> 0 | W26: =IF(AND($D26<=W$17,$E26>=W$16),$C26*NETWORKDAYS(MAX($D26,W$16),MIN($E26,W$17),Hari_Libur)/NETWORKDAYS($D26,$E26,Hari_Libur),0) -> 0 | ... BK26: =IF(AND($D26<=BK$17,$E26>=BK$16),$C26*NETWORKDAYS(MAX($D26,BK$16),MIN($E26,BK$17),Hari_Libur)/NETWORKDAYS($D26,$E26,Hari_Libur),0) -> 0
P27: =IF(AND($D27<=P$17,$E27>=P$16),$C27*NETWORKDAYS(MAX($D27,P$16),MIN($E27,P$17),Libur!$A$2:$A$38)/NETWORKDAYS($D27,$E27,Libur!$A$2:$A$38),0) -> 0 | Q27: =IF(AND($D27<=Q$17,$E27>=Q$16),$C27*NETWORKDAYS(MAX($D27,Q$16),MIN($E27,Q$17),Libur!$A$2:$A$38)/NETWORKDAYS($D27,$E27,Libur!$A$2:$A$38),0) -> 0 | R27: =IF(AND($D27<=R$17,$E27>=R$16),$C27*NETWORKDAYS(MAX($D27,R$16),MIN($E27,R$17),Libur!$A$2:$A$38)/NETWORKDAYS($D27,$E27,Libur!$A$2:$A$38),0) -> 0 | S27: =IF(AND($D27<=S$17,$E27>=S$16),$C27*NETWORKDAYS(MAX($D27,S$16),MIN($E27,S$17),Libur!$A$2:$A$38)/NETWORKDAYS($D27,$E27,Libur!$A$2:$A$38),0) -> 0 | T27: =IF(AND($D27<=T$17,$E27>=T$16),$C27*NETWORKDAYS(MAX($D27,T$16),MIN($E27,T$17),Libur!$A$2:$A$38)/NETWORKDAYS($D27,$E27,Libur!$A$2:$A$38),0) -> 0 | U27: =IF(AND($D27<=U$17,$E27>=U$16),$C27*NETWORKDAYS(MAX($D27,U$16),MIN($E27,U$17),Libur!$A$2:$A$38)/NETWORKDAYS($D27,$E27,Libur!$A$2:$A$38),0) -> 0 | V27: =IF(AND($D27<=V$17,$E27>=V$16),$C27*NETWORKDAYS(MAX($D27,V$16),MIN($E27,V$17),Libur!$A$2:$A$38)/NETWORKDAYS($D27,$E27,Libur!$A$2:$A$38),0) -> 0 | W27: =IF(AND($D27<=W$17,$E27>=W$16),$C27*NETWORKDAYS(MAX($D27,W$16),MIN($E27,W$17),Libur!$A$2:$A$38)/NETWORKDAYS($D27,$E27,Libur!$A$2:$A$38),0) -> 0 | ... BK27: =IF(AND($D27<=BK$17,$E27>=BK$16),$C27*NETWORKDAYS(MAX($D27,BK$16),MIN($E27,BK$17),Libur!$A$2:$A$38)/NETWORKDAYS($D27,$E27,Libur!$A$2:$A$38),0) -> 0
A28: III | B28: REQUIREMENT | C28: =SUM(C29:C30) -> 0.1 | D28: =MIN(D29:D30) -> 46153 | E28: =MAX(E29:E30) -> 46168 | H28: =NETWORKDAYS(D28,E28,Hari_Libur) -> 10 | I28: =IF(C28=0,0,J28/C28) -> 0.21428571 | J28: =SUM(J29:J30) -> 0.021428571 | K28: =IF(C28=0,0,L28/C28) -> 0.25 | L28: =SUM(L29:L30) -> 0.025 | M28: =SUM(M29:M30) -> 0.0035714286
B29: Requirement | C29: 0.05 | D29: 46153 | E29: 46163 | F29: =C29 -> 0.05 | G29: =SUM(P29:AZ29) -> 0.05 | H29: =NETWORKDAYS(D29,E29,Hari_Libur) -> 7 | I29: =IF($C$8>=E29,1,IF($C$8<D29,0,IF(NETWORKDAYS(D29,E29,Hari_Libur)=0,0,NETWORKDAYS(D29,$C$8,Hari_Libur)/NETWORKDAYS(D29,E29,Hari_Libur)))) -> 0.42857143 | J29: =I29*F29 -> 0.021428571 | K29: 0.5 | L29: =C29*K29 -> 0.025 | M29: =L29-J29 -> 0.0035714286 | N29: =C29 -> 0.05 | O29: =SUM(P29:BK29) -> 0.05 | P29: =IF(AND($D29<=P$17,$E29>=P$16),$C29*NETWORKDAYS(MAX($D29,P$16),MIN($E29,P$17),Hari_Libur)/NETWORKDAYS($D29,$E29,Hari_Libur),0) -> 0.021428571 | Q29: =IF(AND($D29<=Q$17,$E29>=Q$16),$C29*NETWORKDAYS(MAX($D29,Q$16),MIN($E29,Q$17),Hari_Libur)/NETWORKDAYS($D29,$E29,Hari_Libur),0) -> 0.028571429 | R29: =IF(AND($D29<=R$17,$E29>=R$16),$C29*NETWORKDAYS(MAX($D29,R$16),MIN($E29,R$17),Hari_Libur)/NETWORKDAYS($D29,$E29,Hari_Libur),0) -> 0 | S29: =IF(AND($D29<=S$17,$E29>=S$16),$C29*NETWORKDAYS(MAX($D29,S$16),MIN($E29,S$17),Hari_Libur)/NETWORKDAYS($D29,$E29,Hari_Libur),0) -> 0 | T29: =IF(AND($D29<=T$17,$E29>=T$16),$C29*NETWORKDAYS(MAX($D29,T$16),MIN($E29,T$17),Hari_Libur)/NETWORKDAYS($D29,$E29,Hari_Libur),0) -> 0 | U29: =IF(AND($D29<=U$17,$E29>=U$16),$C29*NETWORKDAYS(MAX($D29,U$16),MIN($E29,U$17),Hari_Libur)/NETWORKDAYS($D29,$E29,Hari_Libur),0) -> 0 | V29: =IF(AND($D29<=V$17,$E29>=V$16),$C29*NETWORKDAYS(MAX($D29,V$16),MIN($E29,V$17),Hari_Libur)/NETWORKDAYS($D29,$E29,Hari_Libur),0) -> 0 | W29: =IF(AND($D29<=W$17,$E29>=W$16),$C29*NETWORKDAYS(MAX($D29,W$16),MIN($E29,W$17),Hari_Libur)/NETWORKDAYS($D29,$E29,Hari_Libur),0) -> 0 | ... BK29: =IF(AND($D29<=BK$17,$E29>=BK$16),$C29*NETWORKDAYS(MAX($D29,BK$16),MIN($E29,BK$17),Hari_Libur)/NETWORKDAYS($D29,$E29,Hari_Libur),0) -> 0
B30: Requirement Finalize | C30: 0.05 | D30: 46164 | E30: 46168 | F30: =C30 -> 0.05 | G30: =SUM(P30:AZ30) -> 0.05 | H30: =NETWORKDAYS(D30,E30,Hari_Libur) -> 3 | I30: =IF($C$8>=E30,1,IF($C$8<D30,0,IF(NETWORKDAYS(D30,E30,Hari_Libur)=0,0,NETWORKDAYS(D30,$C$8,Hari_Libur)/NETWORKDAYS(D30,E30,Hari_Libur)))) -> 0 | J30: =I30*F30 -> 0 | K30: 0 | L30: =C30*K30 -> 0 | M30: =L30-J30 -> 0 | N30: =C30 -> 0.05 | O30: =SUM(P30:BK30) -> 0.05 | P30: =IF(AND($D30<=P$17,$E30>=P$16),$C30*NETWORKDAYS(MAX($D30,P$16),MIN($E30,P$17),Hari_Libur)/NETWORKDAYS($D30,$E30,Hari_Libur),0) -> 0 | Q30: =IF(AND($D30<=Q$17,$E30>=Q$16),$C30*NETWORKDAYS(MAX($D30,Q$16),MIN($E30,Q$17),Hari_Libur)/NETWORKDAYS($D30,$E30,Hari_Libur),0) -> 0 | R30: =IF(AND($D30<=R$17,$E30>=R$16),$C30*NETWORKDAYS(MAX($D30,R$16),MIN($E30,R$17),Hari_Libur)/NETWORKDAYS($D30,$E30,Hari_Libur),0) -> 0.05 | S30: =IF(AND($D30<=S$17,$E30>=S$16),$C30*NETWORKDAYS(MAX($D30,S$16),MIN($E30,S$17),Hari_Libur)/NETWORKDAYS($D30,$E30,Hari_Libur),0) -> 0 | T30: =IF(AND($D30<=T$17,$E30>=T$16),$C30*NETWORKDAYS(MAX($D30,T$16),MIN($E30,T$17),Hari_Libur)/NETWORKDAYS($D30,$E30,Hari_Libur),0) -> 0 | U30: =IF(AND($D30<=U$17,$E30>=U$16),$C30*NETWORKDAYS(MAX($D30,U$16),MIN($E30,U$17),Hari_Libur)/NETWORKDAYS($D30,$E30,Hari_Libur),0) -> 0 | V30: =IF(AND($D30<=V$17,$E30>=V$16),$C30*NETWORKDAYS(MAX($D30,V$16),MIN($E30,V$17),Hari_Libur)/NETWORKDAYS($D30,$E30,Hari_Libur),0) -> 0 | W30: =IF(AND($D30<=W$17,$E30>=W$16),$C30*NETWORKDAYS(MAX($D30,W$16),MIN($E30,W$17),Hari_Libur)/NETWORKDAYS($D30,$E30,Hari_Libur),0) -> 0 | ... BK30: =IF(AND($D30<=BK$17,$E30>=BK$16),$C30*NETWORKDAYS(MAX($D30,BK$16),MIN($E30,BK$17),Hari_Libur)/NETWORKDAYS($D30,$E30,Hari_Libur),0) -> 0
P31: =IF(AND($D31<=P$17,$E31>=P$16),$C31*NETWORKDAYS(MAX($D31,P$16),MIN($E31,P$17),Libur!$A$2:$A$38)/NETWORKDAYS($D31,$E31,Libur!$A$2:$A$38),0) -> 0 | Q31: =IF(AND($D31<=Q$17,$E31>=Q$16),$C31*NETWORKDAYS(MAX($D31,Q$16),MIN($E31,Q$17),Libur!$A$2:$A$38)/NETWORKDAYS($D31,$E31,Libur!$A$2:$A$38),0) -> 0 | R31: =IF(AND($D31<=R$17,$E31>=R$16),$C31*NETWORKDAYS(MAX($D31,R$16),MIN($E31,R$17),Libur!$A$2:$A$38)/NETWORKDAYS($D31,$E31,Libur!$A$2:$A$38),0) -> 0 | S31: =IF(AND($D31<=S$17,$E31>=S$16),$C31*NETWORKDAYS(MAX($D31,S$16),MIN($E31,S$17),Libur!$A$2:$A$38)/NETWORKDAYS($D31,$E31,Libur!$A$2:$A$38),0) -> 0 | T31: =IF(AND($D31<=T$17,$E31>=T$16),$C31*NETWORKDAYS(MAX($D31,T$16),MIN($E31,T$17),Libur!$A$2:$A$38)/NETWORKDAYS($D31,$E31,Libur!$A$2:$A$38),0) -> 0 | U31: =IF(AND($D31<=U$17,$E31>=U$16),$C31*NETWORKDAYS(MAX($D31,U$16),MIN($E31,U$17),Libur!$A$2:$A$38)/NETWORKDAYS($D31,$E31,Libur!$A$2:$A$38),0) -> 0 | V31: =IF(AND($D31<=V$17,$E31>=V$16),$C31*NETWORKDAYS(MAX($D31,V$16),MIN($E31,V$17),Libur!$A$2:$A$38)/NETWORKDAYS($D31,$E31,Libur!$A$2:$A$38),0) -> 0 | W31: =IF(AND($D31<=W$17,$E31>=W$16),$C31*NETWORKDAYS(MAX($D31,W$16),MIN($E31,W$17),Libur!$A$2:$A$38)/NETWORKDAYS($D31,$E31,Libur!$A$2:$A$38),0) -> 0 | ... BK31: =IF(AND($D31<=BK$17,$E31>=BK$16),$C31*NETWORKDAYS(MAX($D31,BK$16),MIN($E31,BK$17),Libur!$A$2:$A$38)/NETWORKDAYS($D31,$E31,Libur!$A$2:$A$38),0) -> 0
A32: IV | B32: ANALYSIS & DESIGN | C32: =SUM(C33:C36) -> 0.2 | D32: =MIN(D33:D36) -> 46171 | E32: =MAX(E33:E36) -> 46184 | H32: =NETWORKDAYS(D32,E32,Hari_Libur) -> 9 | I32: =IF(C32=0,0,J32/C32) -> 0 | J32: =SUM(J33:J36) -> 0 | K32: =IF(C32=0,0,L32/C32) -> 0 | L32: =SUM(L33:L36) -> 0 | M32: =SUM(M33:M36) -> 0
B33: Analisa | C33: 0.07 | D33: 46171 | E33: 46177 | F33: =C33 -> 0.07 | G33: =SUM(P33:AZ33) -> 0.07 | H33: =NETWORKDAYS(D33,E33,Hari_Libur) -> 4 | I33: =IF($C$8>=E33,1,IF($C$8<D33,0,IF(NETWORKDAYS(D33,E33,Hari_Libur)=0,0,NETWORKDAYS(D33,$C$8,Hari_Libur)/NETWORKDAYS(D33,E33,Hari_Libur)))) -> 0 | J33: =I33*F33 -> 0 | K33: 0 | L33: =C33*K33 -> 0 | M33: =L33-J33 -> 0 | N33: =C33 -> 0.07 | O33: =SUM(P33:BK33) -> 0.07 | P33: =IF(AND($D33<=P$17,$E33>=P$16),$C33*NETWORKDAYS(MAX($D33,P$16),MIN($E33,P$17),Hari_Libur)/NETWORKDAYS($D33,$E33,Hari_Libur),0) -> 0 | Q33: =IF(AND($D33<=Q$17,$E33>=Q$16),$C33*NETWORKDAYS(MAX($D33,Q$16),MIN($E33,Q$17),Hari_Libur)/NETWORKDAYS($D33,$E33,Hari_Libur),0) -> 0 | R33: =IF(AND($D33<=R$17,$E33>=R$16),$C33*NETWORKDAYS(MAX($D33,R$16),MIN($E33,R$17),Hari_Libur)/NETWORKDAYS($D33,$E33,Hari_Libur),0) -> 0 | S33: =IF(AND($D33<=S$17,$E33>=S$16),$C33*NETWORKDAYS(MAX($D33,S$16),MIN($E33,S$17),Hari_Libur)/NETWORKDAYS($D33,$E33,Hari_Libur),0) -> 0.07 | T33: =IF(AND($D33<=T$17,$E33>=T$16),$C33*NETWORKDAYS(MAX($D33,T$16),MIN($E33,T$17),Hari_Libur)/NETWORKDAYS($D33,$E33,Hari_Libur),0) -> 0 | U33: =IF(AND($D33<=U$17,$E33>=U$16),$C33*NETWORKDAYS(MAX($D33,U$16),MIN($E33,U$17),Hari_Libur)/NETWORKDAYS($D33,$E33,Hari_Libur),0) -> 0 | V33: =IF(AND($D33<=V$17,$E33>=V$16),$C33*NETWORKDAYS(MAX($D33,V$16),MIN($E33,V$17),Hari_Libur)/NETWORKDAYS($D33,$E33,Hari_Libur),0) -> 0 | W33: =IF(AND($D33<=W$17,$E33>=W$16),$C33*NETWORKDAYS(MAX($D33,W$16),MIN($E33,W$17),Hari_Libur)/NETWORKDAYS($D33,$E33,Hari_Libur),0) -> 0 | ... BK33: =IF(AND($D33<=BK$17,$E33>=BK$16),$C33*NETWORKDAYS(MAX($D33,BK$16),MIN($E33,BK$17),Hari_Libur)/NETWORKDAYS($D33,$E33,Hari_Libur),0) -> 0
B34: Technical Design | C34: 0.05 | D34: 46178 | E34: 46182 | F34: =C34 -> 0.05 | G34: =SUM(P34:AZ34) -> 0.05 | H34: =NETWORKDAYS(D34,E34,Hari_Libur) -> 3 | I34: =IF($C$8>=E34,1,IF($C$8<D34,0,IF(NETWORKDAYS(D34,E34,Hari_Libur)=0,0,NETWORKDAYS(D34,$C$8,Hari_Libur)/NETWORKDAYS(D34,E34,Hari_Libur)))) -> 0 | J34: =I34*F34 -> 0 | K34: 0 | L34: =C34*K34 -> 0 | M34: =L34-J34 -> 0 | N34: =C34 -> 0.05 | O34: =SUM(P34:BK34) -> 0.05 | P34: =IF(AND($D34<=P$17,$E34>=P$16),$C34*NETWORKDAYS(MAX($D34,P$16),MIN($E34,P$17),Hari_Libur)/NETWORKDAYS($D34,$E34,Hari_Libur),0) -> 0 | Q34: =IF(AND($D34<=Q$17,$E34>=Q$16),$C34*NETWORKDAYS(MAX($D34,Q$16),MIN($E34,Q$17),Hari_Libur)/NETWORKDAYS($D34,$E34,Hari_Libur),0) -> 0 | R34: =IF(AND($D34<=R$17,$E34>=R$16),$C34*NETWORKDAYS(MAX($D34,R$16),MIN($E34,R$17),Hari_Libur)/NETWORKDAYS($D34,$E34,Hari_Libur),0) -> 0 | S34: =IF(AND($D34<=S$17,$E34>=S$16),$C34*NETWORKDAYS(MAX($D34,S$16),MIN($E34,S$17),Hari_Libur)/NETWORKDAYS($D34,$E34,Hari_Libur),0) -> 0 | T34: =IF(AND($D34<=T$17,$E34>=T$16),$C34*NETWORKDAYS(MAX($D34,T$16),MIN($E34,T$17),Hari_Libur)/NETWORKDAYS($D34,$E34,Hari_Libur),0) -> 0.05 | U34: =IF(AND($D34<=U$17,$E34>=U$16),$C34*NETWORKDAYS(MAX($D34,U$16),MIN($E34,U$17),Hari_Libur)/NETWORKDAYS($D34,$E34,Hari_Libur),0) -> 0 | V34: =IF(AND($D34<=V$17,$E34>=V$16),$C34*NETWORKDAYS(MAX($D34,V$16),MIN($E34,V$17),Hari_Libur)/NETWORKDAYS($D34,$E34,Hari_Libur),0) -> 0 | W34: =IF(AND($D34<=W$17,$E34>=W$16),$C34*NETWORKDAYS(MAX($D34,W$16),MIN($E34,W$17),Hari_Libur)/NETWORKDAYS($D34,$E34,Hari_Libur),0) -> 0 | ... BK34: =IF(AND($D34<=BK$17,$E34>=BK$16),$C34*NETWORKDAYS(MAX($D34,BK$16),MIN($E34,BK$17),Hari_Libur)/NETWORKDAYS($D34,$E34,Hari_Libur),0) -> 0
B35: Design Review & Fix | C35: 0.03 | D35: 46183 | E35: 46184 | F35: =C35 -> 0.03 | G35: =SUM(P35:AZ35) -> 0.03 | H35: =NETWORKDAYS(D35,E35,Hari_Libur) -> 2 | I35: =IF($C$8>=E35,1,IF($C$8<D35,0,IF(NETWORKDAYS(D35,E35,Hari_Libur)=0,0,NETWORKDAYS(D35,$C$8,Hari_Libur)/NETWORKDAYS(D35,E35,Hari_Libur)))) -> 0 | J35: =I35*F35 -> 0 | K35: 0 | L35: =C35*K35 -> 0 | M35: =L35-J35 -> 0 | N35: =C35 -> 0.03 | O35: =SUM(P35:BK35) -> 0.03 | P35: =IF(AND($D35<=P$17,$E35>=P$16),$C35*NETWORKDAYS(MAX($D35,P$16),MIN($E35,P$17),Hari_Libur)/NETWORKDAYS($D35,$E35,Hari_Libur),0) -> 0 | Q35: =IF(AND($D35<=Q$17,$E35>=Q$16),$C35*NETWORKDAYS(MAX($D35,Q$16),MIN($E35,Q$17),Hari_Libur)/NETWORKDAYS($D35,$E35,Hari_Libur),0) -> 0 | R35: =IF(AND($D35<=R$17,$E35>=R$16),$C35*NETWORKDAYS(MAX($D35,R$16),MIN($E35,R$17),Hari_Libur)/NETWORKDAYS($D35,$E35,Hari_Libur),0) -> 0 | S35: =IF(AND($D35<=S$17,$E35>=S$16),$C35*NETWORKDAYS(MAX($D35,S$16),MIN($E35,S$17),Hari_Libur)/NETWORKDAYS($D35,$E35,Hari_Libur),0) -> 0 | T35: =IF(AND($D35<=T$17,$E35>=T$16),$C35*NETWORKDAYS(MAX($D35,T$16),MIN($E35,T$17),Hari_Libur)/NETWORKDAYS($D35,$E35,Hari_Libur),0) -> 0.03 | U35: =IF(AND($D35<=U$17,$E35>=U$16),$C35*NETWORKDAYS(MAX($D35,U$16),MIN($E35,U$17),Hari_Libur)/NETWORKDAYS($D35,$E35,Hari_Libur),0) -> 0 | V35: =IF(AND($D35<=V$17,$E35>=V$16),$C35*NETWORKDAYS(MAX($D35,V$16),MIN($E35,V$17),Hari_Libur)/NETWORKDAYS($D35,$E35,Hari_Libur),0) -> 0 | W35: =IF(AND($D35<=W$17,$E35>=W$16),$C35*NETWORKDAYS(MAX($D35,W$16),MIN($E35,W$17),Hari_Libur)/NETWORKDAYS($D35,$E35,Hari_Libur),0) -> 0 | ... BK35: =IF(AND($D35<=BK$17,$E35>=BK$16),$C35*NETWORKDAYS(MAX($D35,BK$16),MIN($E35,BK$17),Hari_Libur)/NETWORKDAYS($D35,$E35,Hari_Libur),0) -> 0
B36: Design Sign off | C36: 0.05 | D36: 46184 | E36: 46184 | F36: =C36 -> 0.05 | G36: =SUM(P36:AZ36) -> 0.05 | H36: =NETWORKDAYS(D36,E36,Hari_Libur) -> 1 | I36: =IF($C$8>=E36,1,IF($C$8<D36,0,IF(NETWORKDAYS(D36,E36,Hari_Libur)=0,0,NETWORKDAYS(D36,$C$8,Hari_Libur)/NETWORKDAYS(D36,E36,Hari_Libur)))) -> 0 | J36: =I36*F36 -> 0 | K36: 0 | L36: =C36*K36 -> 0 | M36: =L36-J36 -> 0 | N36: =C36 -> 0.05 | O36: =SUM(P36:BK36) -> 0.05 | P36: =IF(AND($D36<=P$17,$E36>=P$16),$C36*NETWORKDAYS(MAX($D36,P$16),MIN($E36,P$17),Hari_Libur)/NETWORKDAYS($D36,$E36,Hari_Libur),0) -> 0 | Q36: =IF(AND($D36<=Q$17,$E36>=Q$16),$C36*NETWORKDAYS(MAX($D36,Q$16),MIN($E36,Q$17),Hari_Libur)/NETWORKDAYS($D36,$E36,Hari_Libur),0) -> 0 | R36: =IF(AND($D36<=R$17,$E36>=R$16),$C36*NETWORKDAYS(MAX($D36,R$16),MIN($E36,R$17),Hari_Libur)/NETWORKDAYS($D36,$E36,Hari_Libur),0) -> 0 | S36: =IF(AND($D36<=S$17,$E36>=S$16),$C36*NETWORKDAYS(MAX($D36,S$16),MIN($E36,S$17),Hari_Libur)/NETWORKDAYS($D36,$E36,Hari_Libur),0) -> 0 | T36: =IF(AND($D36<=T$17,$E36>=T$16),$C36*NETWORKDAYS(MAX($D36,T$16),MIN($E36,T$17),Hari_Libur)/NETWORKDAYS($D36,$E36,Hari_Libur),0) -> 0.05 | U36: =IF(AND($D36<=U$17,$E36>=U$16),$C36*NETWORKDAYS(MAX($D36,U$16),MIN($E36,U$17),Hari_Libur)/NETWORKDAYS($D36,$E36,Hari_Libur),0) -> 0 | V36: =IF(AND($D36<=V$17,$E36>=V$16),$C36*NETWORKDAYS(MAX($D36,V$16),MIN($E36,V$17),Hari_Libur)/NETWORKDAYS($D36,$E36,Hari_Libur),0) -> 0 | W36: =IF(AND($D36<=W$17,$E36>=W$16),$C36*NETWORKDAYS(MAX($D36,W$16),MIN($E36,W$17),Hari_Libur)/NETWORKDAYS($D36,$E36,Hari_Libur),0) -> 0 | ... BK36: =IF(AND($D36<=BK$17,$E36>=BK$16),$C36*NETWORKDAYS(MAX($D36,BK$16),MIN($E36,BK$17),Hari_Libur)/NETWORKDAYS($D36,$E36,Hari_Libur),0) -> 0
P37: =IF(AND($D37<=P$17,$E37>=P$16),$C37*NETWORKDAYS(MAX($D37,P$16),MIN($E37,P$17),Libur!$A$2:$A$38)/NETWORKDAYS($D37,$E37,Libur!$A$2:$A$38),0) -> 0 | Q37: =IF(AND($D37<=Q$17,$E37>=Q$16),$C37*NETWORKDAYS(MAX($D37,Q$16),MIN($E37,Q$17),Libur!$A$2:$A$38)/NETWORKDAYS($D37,$E37,Libur!$A$2:$A$38),0) -> 0 | R37: =IF(AND($D37<=R$17,$E37>=R$16),$C37*NETWORKDAYS(MAX($D37,R$16),MIN($E37,R$17),Libur!$A$2:$A$38)/NETWORKDAYS($D37,$E37,Libur!$A$2:$A$38),0) -> 0 | S37: =IF(AND($D37<=S$17,$E37>=S$16),$C37*NETWORKDAYS(MAX($D37,S$16),MIN($E37,S$17),Libur!$A$2:$A$38)/NETWORKDAYS($D37,$E37,Libur!$A$2:$A$38),0) -> 0 | T37: =IF(AND($D37<=T$17,$E37>=T$16),$C37*NETWORKDAYS(MAX($D37,T$16),MIN($E37,T$17),Libur!$A$2:$A$38)/NETWORKDAYS($D37,$E37,Libur!$A$2:$A$38),0) -> 0 | U37: =IF(AND($D37<=U$17,$E37>=U$16),$C37*NETWORKDAYS(MAX($D37,U$16),MIN($E37,U$17),Libur!$A$2:$A$38)/NETWORKDAYS($D37,$E37,Libur!$A$2:$A$38),0) -> 0 | V37: =IF(AND($D37<=V$17,$E37>=V$16),$C37*NETWORKDAYS(MAX($D37,V$16),MIN($E37,V$17),Libur!$A$2:$A$38)/NETWORKDAYS($D37,$E37,Libur!$A$2:$A$38),0) -> 0 | W37: =IF(AND($D37<=W$17,$E37>=W$16),$C37*NETWORKDAYS(MAX($D37,W$16),MIN($E37,W$17),Libur!$A$2:$A$38)/NETWORKDAYS($D37,$E37,Libur!$A$2:$A$38),0) -> 0 | ... BK37: =IF(AND($D37<=BK$17,$E37>=BK$16),$C37*NETWORKDAYS(MAX($D37,BK$16),MIN($E37,BK$17),Libur!$A$2:$A$38)/NETWORKDAYS($D37,$E37,Libur!$A$2:$A$38),0) -> 0
A38: V | B38: DEVELOPMENT | C38: =SUM(C39:C41) -> 0.42 | D38: =MIN(D39:D41) -> 46185 | E38: =MAX(E39:E41) -> 46219 | H38: =NETWORKDAYS(D38,E38,Hari_Libur) -> 24 | I38: =IF(C38=0,0,J38/C38) -> 0 | J38: =SUM(J39:J41) -> 0 | K38: =IF(C38=0,0,L38/C38) -> 0 | L38: =SUM(L39:L41) -> 0 | M38: =SUM(M39:M41) -> 0
B39: Core Feature Development | C39: 0.15 | D39: 46185 | E39: 46205 | F39: =C39 -> 0.15 | G39: =SUM(P39:AZ39) -> 0.15 | H39: =NETWORKDAYS(D39,E39,Hari_Libur) -> 14 | I39: =IF($C$8>=E39,1,IF($C$8<D39,0,IF(NETWORKDAYS(D39,E39,Hari_Libur)=0,0,NETWORKDAYS(D39,$C$8,Hari_Libur)/NETWORKDAYS(D39,E39,Hari_Libur)))) -> 0 | J39: =I39*F39 -> 0 | K39: 0 | L39: =C39*K39 -> 0 | M39: =L39-J39 -> 0 | N39: =C39 -> 0.15 | O39: =SUM(P39:BK39) -> 0.15 | P39: =IF(AND($D39<=P$17,$E39>=P$16),$C39*NETWORKDAYS(MAX($D39,P$16),MIN($E39,P$17),Hari_Libur)/NETWORKDAYS($D39,$E39,Hari_Libur),0) -> 0 | Q39: =IF(AND($D39<=Q$17,$E39>=Q$16),$C39*NETWORKDAYS(MAX($D39,Q$16),MIN($E39,Q$17),Hari_Libur)/NETWORKDAYS($D39,$E39,Hari_Libur),0) -> 0 | R39: =IF(AND($D39<=R$17,$E39>=R$16),$C39*NETWORKDAYS(MAX($D39,R$16),MIN($E39,R$17),Hari_Libur)/NETWORKDAYS($D39,$E39,Hari_Libur),0) -> 0 | S39: =IF(AND($D39<=S$17,$E39>=S$16),$C39*NETWORKDAYS(MAX($D39,S$16),MIN($E39,S$17),Hari_Libur)/NETWORKDAYS($D39,$E39,Hari_Libur),0) -> 0 | T39: =IF(AND($D39<=T$17,$E39>=T$16),$C39*NETWORKDAYS(MAX($D39,T$16),MIN($E39,T$17),Hari_Libur)/NETWORKDAYS($D39,$E39,Hari_Libur),0) -> 0 | U39: =IF(AND($D39<=U$17,$E39>=U$16),$C39*NETWORKDAYS(MAX($D39,U$16),MIN($E39,U$17),Hari_Libur)/NETWORKDAYS($D39,$E39,Hari_Libur),0) -> 0.042857143 | V39: =IF(AND($D39<=V$17,$E39>=V$16),$C39*NETWORKDAYS(MAX($D39,V$16),MIN($E39,V$17),Hari_Libur)/NETWORKDAYS($D39,$E39,Hari_Libur),0) -> 0.053571429 | W39: =IF(AND($D39<=W$17,$E39>=W$16),$C39*NETWORKDAYS(MAX($D39,W$16),MIN($E39,W$17),Hari_Libur)/NETWORKDAYS($D39,$E39,Hari_Libur),0) -> 0.053571429 | ... BK39: =IF(AND($D39<=BK$17,$E39>=BK$16),$C39*NETWORKDAYS(MAX($D39,BK$16),MIN($E39,BK$17),Hari_Libur)/NETWORKDAYS($D39,$E39,Hari_Libur),0) -> 0
B40: Integration (Guci & Ossera) | C40: 0.15 | D40: 46189 | E40: 46212 | F40: =C40 -> 0.15 | G40: =SUM(P40:AZ40) -> 0.15 | H40: =NETWORKDAYS(D40,E40,Hari_Libur) -> 17 | I40: =IF($C$8>=E40,1,IF($C$8<D40,0,IF(NETWORKDAYS(D40,E40,Hari_Libur)=0,0,NETWORKDAYS(D40,$C$8,Hari_Libur)/NETWORKDAYS(D40,E40,Hari_Libur)))) -> 0 | J40: =I40*F40 -> 0 | K40: 0 | L40: =C40*K40 -> 0 | M40: =L40-J40 -> 0 | N40: =C40 -> 0.15 | O40: =SUM(P40:BK40) -> 0.15 | P40: =IF(AND($D40<=P$17,$E40>=P$16),$C40*NETWORKDAYS(MAX($D40,P$16),MIN($E40,P$17),Hari_Libur)/NETWORKDAYS($D40,$E40,Hari_Libur),0) -> 0 | Q40: =IF(AND($D40<=Q$17,$E40>=Q$16),$C40*NETWORKDAYS(MAX($D40,Q$16),MIN($E40,Q$17),Hari_Libur)/NETWORKDAYS($D40,$E40,Hari_Libur),0) -> 0 | R40: =IF(AND($D40<=R$17,$E40>=R$16),$C40*NETWORKDAYS(MAX($D40,R$16),MIN($E40,R$17),Hari_Libur)/NETWORKDAYS($D40,$E40,Hari_Libur),0) -> 0 | S40: =IF(AND($D40<=S$17,$E40>=S$16),$C40*NETWORKDAYS(MAX($D40,S$16),MIN($E40,S$17),Hari_Libur)/NETWORKDAYS($D40,$E40,Hari_Libur),0) -> 0 | T40: =IF(AND($D40<=T$17,$E40>=T$16),$C40*NETWORKDAYS(MAX($D40,T$16),MIN($E40,T$17),Hari_Libur)/NETWORKDAYS($D40,$E40,Hari_Libur),0) -> 0 | U40: =IF(AND($D40<=U$17,$E40>=U$16),$C40*NETWORKDAYS(MAX($D40,U$16),MIN($E40,U$17),Hari_Libur)/NETWORKDAYS($D40,$E40,Hari_Libur),0) -> 0.017647059 | V40: =IF(AND($D40<=V$17,$E40>=V$16),$C40*NETWORKDAYS(MAX($D40,V$16),MIN($E40,V$17),Hari_Libur)/NETWORKDAYS($D40,$E40,Hari_Libur),0) -> 0.044117647 | W40: =IF(AND($D40<=W$17,$E40>=W$16),$C40*NETWORKDAYS(MAX($D40,W$16),MIN($E40,W$17),Hari_Libur)/NETWORKDAYS($D40,$E40,Hari_Libur),0) -> 0.044117647 | ... BK40: =IF(AND($D40<=BK$17,$E40>=BK$16),$C40*NETWORKDAYS(MAX($D40,BK$16),MIN($E40,BK$17),Hari_Libur)/NETWORKDAYS($D40,$E40,Hari_Libur),0) -> 0
B41: Bug Fixing Cycle | C41: 0.12 | D41: 46213 | E41: 46219 | F41: =C41 -> 0.12 | G41: =SUM(P41:AZ41) -> 0.12 | H41: =NETWORKDAYS(D41,E41,Hari_Libur) -> 5 | I41: =IF($C$8>=E41,1,IF($C$8<D41,0,IF(NETWORKDAYS(D41,E41,Hari_Libur)=0,0,NETWORKDAYS(D41,$C$8,Hari_Libur)/NETWORKDAYS(D41,E41,Hari_Libur)))) -> 0 | J41: =I41*F41 -> 0 | K41: 0 | L41: =C41*K41 -> 0 | M41: =L41-J41 -> 0 | N41: =C41 -> 0.12 | O41: =SUM(P41:BK41) -> 0.12 | P41: =IF(AND($D41<=P$17,$E41>=P$16),$C41*NETWORKDAYS(MAX($D41,P$16),MIN($E41,P$17),Hari_Libur)/NETWORKDAYS($D41,$E41,Hari_Libur),0) -> 0 | Q41: =IF(AND($D41<=Q$17,$E41>=Q$16),$C41*NETWORKDAYS(MAX($D41,Q$16),MIN($E41,Q$17),Hari_Libur)/NETWORKDAYS($D41,$E41,Hari_Libur),0) -> 0 | R41: =IF(AND($D41<=R$17,$E41>=R$16),$C41*NETWORKDAYS(MAX($D41,R$16),MIN($E41,R$17),Hari_Libur)/NETWORKDAYS($D41,$E41,Hari_Libur),0) -> 0 | S41: =IF(AND($D41<=S$17,$E41>=S$16),$C41*NETWORKDAYS(MAX($D41,S$16),MIN($E41,S$17),Hari_Libur)/NETWORKDAYS($D41,$E41,Hari_Libur),0) -> 0 | T41: =IF(AND($D41<=T$17,$E41>=T$16),$C41*NETWORKDAYS(MAX($D41,T$16),MIN($E41,T$17),Hari_Libur)/NETWORKDAYS($D41,$E41,Hari_Libur),0) -> 0 | U41: =IF(AND($D41<=U$17,$E41>=U$16),$C41*NETWORKDAYS(MAX($D41,U$16),MIN($E41,U$17),Hari_Libur)/NETWORKDAYS($D41,$E41,Hari_Libur),0) -> 0 | V41: =IF(AND($D41<=V$17,$E41>=V$16),$C41*NETWORKDAYS(MAX($D41,V$16),MIN($E41,V$17),Hari_Libur)/NETWORKDAYS($D41,$E41,Hari_Libur),0) -> 0 | W41: =IF(AND($D41<=W$17,$E41>=W$16),$C41*NETWORKDAYS(MAX($D41,W$16),MIN($E41,W$17),Hari_Libur)/NETWORKDAYS($D41,$E41,Hari_Libur),0) -> 0 | ... BK41: =IF(AND($D41<=BK$17,$E41>=BK$16),$C41*NETWORKDAYS(MAX($D41,BK$16),MIN($E41,BK$17),Hari_Libur)/NETWORKDAYS($D41,$E41,Hari_Libur),0) -> 0
P42: =IF(AND($D42<=P$17,$E42>=P$16),$C42*NETWORKDAYS(MAX($D42,P$16),MIN($E42,P$17),Libur!$A$2:$A$38)/NETWORKDAYS($D42,$E42,Libur!$A$2:$A$38),0) -> 0 | Q42: =IF(AND($D42<=Q$17,$E42>=Q$16),$C42*NETWORKDAYS(MAX($D42,Q$16),MIN($E42,Q$17),Libur!$A$2:$A$38)/NETWORKDAYS($D42,$E42,Libur!$A$2:$A$38),0) -> 0 | R42: =IF(AND($D42<=R$17,$E42>=R$16),$C42*NETWORKDAYS(MAX($D42,R$16),MIN($E42,R$17),Libur!$A$2:$A$38)/NETWORKDAYS($D42,$E42,Libur!$A$2:$A$38),0) -> 0 | S42: =IF(AND($D42<=S$17,$E42>=S$16),$C42*NETWORKDAYS(MAX($D42,S$16),MIN($E42,S$17),Libur!$A$2:$A$38)/NETWORKDAYS($D42,$E42,Libur!$A$2:$A$38),0) -> 0 | T42: =IF(AND($D42<=T$17,$E42>=T$16),$C42*NETWORKDAYS(MAX($D42,T$16),MIN($E42,T$17),Libur!$A$2:$A$38)/NETWORKDAYS($D42,$E42,Libur!$A$2:$A$38),0) -> 0 | U42: =IF(AND($D42<=U$17,$E42>=U$16),$C42*NETWORKDAYS(MAX($D42,U$16),MIN($E42,U$17),Libur!$A$2:$A$38)/NETWORKDAYS($D42,$E42,Libur!$A$2:$A$38),0) -> 0 | V42: =IF(AND($D42<=V$17,$E42>=V$16),$C42*NETWORKDAYS(MAX($D42,V$16),MIN($E42,V$17),Libur!$A$2:$A$38)/NETWORKDAYS($D42,$E42,Libur!$A$2:$A$38),0) -> 0 | W42: =IF(AND($D42<=W$17,$E42>=W$16),$C42*NETWORKDAYS(MAX($D42,W$16),MIN($E42,W$17),Libur!$A$2:$A$38)/NETWORKDAYS($D42,$E42,Libur!$A$2:$A$38),0) -> 0 | ... BK42: =IF(AND($D42<=BK$17,$E42>=BK$16),$C42*NETWORKDAYS(MAX($D42,BK$16),MIN($E42,BK$17),Libur!$A$2:$A$38)/NETWORKDAYS($D42,$E42,Libur!$A$2:$A$38),0) -> 0
A43: VI | B43: TESTING | C43: =SUM(C44:C49) -> 0.1 | D43: =MIN(D44:D49) -> 46220 | E43: =MAX(E44:E49) -> 46245 | H43: =NETWORKDAYS(D43,E43,Hari_Libur) -> 18 | I43: =IF(C43=0,0,J43/C43) -> 0 | J43: =SUM(J44:J49) -> 0 | K43: =IF(C43=0,0,L43/C43) -> 0 | L43: =SUM(L44:L49) -> 0 | M43: =SUM(M44:M49) -> 0
B44: Internal Testing | C44: 0.02 | D44: 46220 | E44: 46225 | F44: =C44 -> 0.02 | G44: =SUM(P44:AZ44) -> 0.02 | H44: =NETWORKDAYS(D44,E44,Hari_Libur) -> 4 | I44: =IF($C$8>=E44,1,IF($C$8<D44,0,IF(NETWORKDAYS(D44,E44,Hari_Libur)=0,0,NETWORKDAYS(D44,$C$8,Hari_Libur)/NETWORKDAYS(D44,E44,Hari_Libur)))) -> 0 | J44: =I44*F44 -> 0 | K44: 0 | L44: =C44*K44 -> 0 | M44: =L44-J44 -> 0 | N44: =C44 -> 0.02 | O44: =SUM(P44:BK44) -> 0.02 | P44: =IF(AND($D44<=P$17,$E44>=P$16),$C44*NETWORKDAYS(MAX($D44,P$16),MIN($E44,P$17),Hari_Libur)/NETWORKDAYS($D44,$E44,Hari_Libur),0) -> 0 | Q44: =IF(AND($D44<=Q$17,$E44>=Q$16),$C44*NETWORKDAYS(MAX($D44,Q$16),MIN($E44,Q$17),Hari_Libur)/NETWORKDAYS($D44,$E44,Hari_Libur),0) -> 0 | R44: =IF(AND($D44<=R$17,$E44>=R$16),$C44*NETWORKDAYS(MAX($D44,R$16),MIN($E44,R$17),Hari_Libur)/NETWORKDAYS($D44,$E44,Hari_Libur),0) -> 0 | S44: =IF(AND($D44<=S$17,$E44>=S$16),$C44*NETWORKDAYS(MAX($D44,S$16),MIN($E44,S$17),Hari_Libur)/NETWORKDAYS($D44,$E44,Hari_Libur),0) -> 0 | T44: =IF(AND($D44<=T$17,$E44>=T$16),$C44*NETWORKDAYS(MAX($D44,T$16),MIN($E44,T$17),Hari_Libur)/NETWORKDAYS($D44,$E44,Hari_Libur),0) -> 0 | U44: =IF(AND($D44<=U$17,$E44>=U$16),$C44*NETWORKDAYS(MAX($D44,U$16),MIN($E44,U$17),Hari_Libur)/NETWORKDAYS($D44,$E44,Hari_Libur),0) -> 0 | V44: =IF(AND($D44<=V$17,$E44>=V$16),$C44*NETWORKDAYS(MAX($D44,V$16),MIN($E44,V$17),Hari_Libur)/NETWORKDAYS($D44,$E44,Hari_Libur),0) -> 0 | W44: =IF(AND($D44<=W$17,$E44>=W$16),$C44*NETWORKDAYS(MAX($D44,W$16),MIN($E44,W$17),Hari_Libur)/NETWORKDAYS($D44,$E44,Hari_Libur),0) -> 0 | ... BK44: =IF(AND($D44<=BK$17,$E44>=BK$16),$C44*NETWORKDAYS(MAX($D44,BK$16),MIN($E44,BK$17),Hari_Libur)/NETWORKDAYS($D44,$E44,Hari_Libur),0) -> 0
B45: SIT | C45: 0.01 | D45: 46226 | E45: 46231 | F45: =C45 -> 0.01 | G45: =SUM(P45:AZ45) -> 0.01 | H45: =NETWORKDAYS(D45,E45,Hari_Libur) -> 4 | I45: =IF($C$8>=E45,1,IF($C$8<D45,0,IF(NETWORKDAYS(D45,E45,Hari_Libur)=0,0,NETWORKDAYS(D45,$C$8,Hari_Libur)/NETWORKDAYS(D45,E45,Hari_Libur)))) -> 0 | J45: =I45*F45 -> 0 | K45: 0 | L45: =C45*K45 -> 0 | M45: =L45-J45 -> 0 | N45: =C45 -> 0.01 | O45: =SUM(P45:BK45) -> 0.01 | P45: =IF(AND($D45<=P$17,$E45>=P$16),$C45*NETWORKDAYS(MAX($D45,P$16),MIN($E45,P$17),Hari_Libur)/NETWORKDAYS($D45,$E45,Hari_Libur),0) -> 0 | Q45: =IF(AND($D45<=Q$17,$E45>=Q$16),$C45*NETWORKDAYS(MAX($D45,Q$16),MIN($E45,Q$17),Hari_Libur)/NETWORKDAYS($D45,$E45,Hari_Libur),0) -> 0 | R45: =IF(AND($D45<=R$17,$E45>=R$16),$C45*NETWORKDAYS(MAX($D45,R$16),MIN($E45,R$17),Hari_Libur)/NETWORKDAYS($D45,$E45,Hari_Libur),0) -> 0 | S45: =IF(AND($D45<=S$17,$E45>=S$16),$C45*NETWORKDAYS(MAX($D45,S$16),MIN($E45,S$17),Hari_Libur)/NETWORKDAYS($D45,$E45,Hari_Libur),0) -> 0 | T45: =IF(AND($D45<=T$17,$E45>=T$16),$C45*NETWORKDAYS(MAX($D45,T$16),MIN($E45,T$17),Hari_Libur)/NETWORKDAYS($D45,$E45,Hari_Libur),0) -> 0 | U45: =IF(AND($D45<=U$17,$E45>=U$16),$C45*NETWORKDAYS(MAX($D45,U$16),MIN($E45,U$17),Hari_Libur)/NETWORKDAYS($D45,$E45,Hari_Libur),0) -> 0 | V45: =IF(AND($D45<=V$17,$E45>=V$16),$C45*NETWORKDAYS(MAX($D45,V$16),MIN($E45,V$17),Hari_Libur)/NETWORKDAYS($D45,$E45,Hari_Libur),0) -> 0 | W45: =IF(AND($D45<=W$17,$E45>=W$16),$C45*NETWORKDAYS(MAX($D45,W$16),MIN($E45,W$17),Hari_Libur)/NETWORKDAYS($D45,$E45,Hari_Libur),0) -> 0 | ... BK45: =IF(AND($D45<=BK$17,$E45>=BK$16),$C45*NETWORKDAYS(MAX($D45,BK$16),MIN($E45,BK$17),Hari_Libur)/NETWORKDAYS($D45,$E45,Hari_Libur),0) -> 0
B46: SIT Fixing | C46: 0.02 | D46: 46232 | E46: 46234 | F46: =C46 -> 0.02 | G46: =SUM(P46:AZ46) -> 0.02 | H46: =NETWORKDAYS(D46,E46,Hari_Libur) -> 3 | I46: =IF($C$8>=E46,1,IF($C$8<D46,0,IF(NETWORKDAYS(D46,E46,Hari_Libur)=0,0,NETWORKDAYS(D46,$C$8,Hari_Libur)/NETWORKDAYS(D46,E46,Hari_Libur)))) -> 0 | J46: =I46*F46 -> 0 | K46: 0 | L46: =C46*K46 -> 0 | M46: =L46-J46 -> 0 | N46: =C46 -> 0.02 | O46: =SUM(P46:BK46) -> 0.02 | P46: =IF(AND($D46<=P$17,$E46>=P$16),$C46*NETWORKDAYS(MAX($D46,P$16),MIN($E46,P$17),Hari_Libur)/NETWORKDAYS($D46,$E46,Hari_Libur),0) -> 0 | Q46: =IF(AND($D46<=Q$17,$E46>=Q$16),$C46*NETWORKDAYS(MAX($D46,Q$16),MIN($E46,Q$17),Hari_Libur)/NETWORKDAYS($D46,$E46,Hari_Libur),0) -> 0 | R46: =IF(AND($D46<=R$17,$E46>=R$16),$C46*NETWORKDAYS(MAX($D46,R$16),MIN($E46,R$17),Hari_Libur)/NETWORKDAYS($D46,$E46,Hari_Libur),0) -> 0 | S46: =IF(AND($D46<=S$17,$E46>=S$16),$C46*NETWORKDAYS(MAX($D46,S$16),MIN($E46,S$17),Hari_Libur)/NETWORKDAYS($D46,$E46,Hari_Libur),0) -> 0 | T46: =IF(AND($D46<=T$17,$E46>=T$16),$C46*NETWORKDAYS(MAX($D46,T$16),MIN($E46,T$17),Hari_Libur)/NETWORKDAYS($D46,$E46,Hari_Libur),0) -> 0 | U46: =IF(AND($D46<=U$17,$E46>=U$16),$C46*NETWORKDAYS(MAX($D46,U$16),MIN($E46,U$17),Hari_Libur)/NETWORKDAYS($D46,$E46,Hari_Libur),0) -> 0 | V46: =IF(AND($D46<=V$17,$E46>=V$16),$C46*NETWORKDAYS(MAX($D46,V$16),MIN($E46,V$17),Hari_Libur)/NETWORKDAYS($D46,$E46,Hari_Libur),0) -> 0 | W46: =IF(AND($D46<=W$17,$E46>=W$16),$C46*NETWORKDAYS(MAX($D46,W$16),MIN($E46,W$17),Hari_Libur)/NETWORKDAYS($D46,$E46,Hari_Libur),0) -> 0 | ... BK46: =IF(AND($D46<=BK$17,$E46>=BK$16),$C46*NETWORKDAYS(MAX($D46,BK$16),MIN($E46,BK$17),Hari_Libur)/NETWORKDAYS($D46,$E46,Hari_Libur),0) -> 0
...

Sheet Log_Mingguan
A1: Log Mingguan – Auto Bandwidth on Demand
A2: Cara pakai: (1) update % progress task di sheet SCurve kolom K dan Status Date di SCurve!C8; (2) di akhir minggu, copy nilai SCurve!C11 (Actual live) lalu Paste Special > Values ke kolom 'Actual Kumulatif' baris minggu tsb. Sel bertulisan biru = input.
A3: Status date | B3: Minggu berjalan | C3: Target (live) | D3: Actual (live) | E3: Deviasi (pp) | F3: SPI | G3: RAG | K3: Ambang Hijau (SPI ≥) | L3: Ambang Kuning (SPI ≥) | N3: Kontrol model | O3: Status
A4: =SCurve!C8 -> 46156 | B4: =COUNTIF(SCurve!$P$17:$BK$17,"<"&SCurve!$C$8)+1 -> 1 | C4: =SCurve!B11 -> 0.051428571 | D4: =SCurve!C11 -> 0.055 | E4: =SCurve!D11 -> 0.0035714286 | F4: =IF(C4=0,"",D4/C4) -> 1.0694444 | G4: =IF(NOT(ISNUMBER(F4)),"",IF(F4>=$K$4,"Hijau",IF(F4>=$L$4,"Kuning","Merah"))) -> Hijau | K4: 0.95 | L4: 0.85 | N4: Total bobot = 100% | O4: =IF(ABS(SCurve!C62-1)<0.000001,"OK","CEK") -> OK
K5: Asumsi: ambang RAG bawaan saya (bukan dari Anda/klien) – sesuaikan dengan kebijakan PMO. | N5: Σ rencana mingguan = 100% | O5: =IF(ABS(SUM(SCurve!P62:BK62)-1)<0.000001,"OK","CEK") -> OK
N6: Σ per-task = bobot task | O6: =IF(ABS(SCurve!O62-SCurve!C62)<0.000001,"OK","CEK") -> OK
A7: Week | B7: Mulai | C7: Akhir | D7: Actual Kumulatif | E7: Target Kumulatif | F7: Deviasi (pp) | G7: SPI | H7: RAG | I7: Catatan / highlight minggu ini
A8: 1 | B8: =INDEX(SCurve!$P$16:$BK$16,A8) -> 46149 | C8: =INDEX(SCurve!$P$17:$BK$17,A8) -> 46156 | D8: 0.055 | E8: =INDEX(SCurve!$P$67:$BK$67,A8) -> 0.051428571 | F8: =IF(ISNUMBER(D8),D8-E8,"") -> 0.0035714286 | G8: =IF(ISNUMBER(D8),IF(E8=0,"",D8/E8),"") -> 1.0694444 | H8: =IF(NOT(ISNUMBER(G8)),"",IF(G8>=$K$4,"Hijau",IF(G8>=$L$4,"Kuning","Merah"))) -> Hijau | I8: Snapshot status 14 Mei 2026 = SCurve!L62 (5,5%). Di file lama tampil 6% karena ROUNDUP. Nilai ini diketik manual (hardcode) sebagai contoh isian.
A9: 2 | B9: =INDEX(SCurve!$P$16:$BK$16,A9) -> 46157 | C9: =INDEX(SCurve!$P$17:$BK$17,A9) -> 46163 | E9: =INDEX(SCurve!$P$67:$BK$67,A9) -> 0.1 | F9: =IF(ISNUMBER(D9),D9-E9,"") | G9: =IF(ISNUMBER(D9),IF(E9=0,"",D9/E9),"") | H9: =IF(NOT(ISNUMBER(G9)),"",IF(G9>=$K$4,"Hijau",IF(G9>=$L$4,"Kuning","Merah")))
A10: 3 | B10: =INDEX(SCurve!$P$16:$BK$16,A10) -> 46164 | C10: =INDEX(SCurve!$P$17:$BK$17,A10) -> 46170 | E10: =INDEX(SCurve!$P$67:$BK$67,A10) -> 0.15 | F10: =IF(ISNUMBER(D10),D10-E10,"") | G10: =IF(ISNUMBER(D10),IF(E10=0,"",D10/E10),"") | H10: =IF(NOT(ISNUMBER(G10)),"",IF(G10>=$K$4,"Hijau",IF(G10>=$L$4,"Kuning","Merah")))
A11: 4 | B11: =INDEX(SCurve!$P$16:$BK$16,A11) -> 46171 | C11: =INDEX(SCurve!$P$17:$BK$17,A11) -> 46177 | E11: =INDEX(SCurve!$P$67:$BK$67,A11) -> 0.22 | F11: =IF(ISNUMBER(D11),D11-E11,"") | G11: =IF(ISNUMBER(D11),IF(E11=0,"",D11/E11),"") | H11: =IF(NOT(ISNUMBER(G11)),"",IF(G11>=$K$4,"Hijau",IF(G11>=$L$4,"Kuning","Merah")))
A12: 5 | B12: =INDEX(SCurve!$P$16:$BK$16,A12) -> 46178 | C12: =INDEX(SCurve!$P$17:$BK$17,A12) -> 46184 | E12: =INDEX(SCurve!$P$67:$BK$67,A12) -> 0.35 | F12: =IF(ISNUMBER(D12),D12-E12,"") | G12: =IF(ISNUMBER(D12),IF(E12=0,"",D12/E12),"") | H12: =IF(NOT(ISNUMBER(G12)),"",IF(G12>=$K$4,"Hijau",IF(G12>=$L$4,"Kuning","Merah")))
A13: 6 | B13: =INDEX(SCurve!$P$16:$BK$16,A13) -> 46185 | C13: =INDEX(SCurve!$P$17:$BK$17,A13) -> 46191 | E13: =INDEX(SCurve!$P$67:$BK$67,A13) -> 0.4105042 | F13: =IF(ISNUMBER(D13),D13-E13,"") | G13: =IF(ISNUMBER(D13),IF(E13=0,"",D13/E13),"") | H13: =IF(NOT(ISNUMBER(G13)),"",IF(G13>=$K$4,"Hijau",IF(G13>=$L$4,"Kuning","Merah")))
A14: 7 | B14: =INDEX(SCurve!$P$16:$BK$16,A14) -> 46192 | C14: =INDEX(SCurve!$P$17:$BK$17,A14) -> 46198 | E14: =INDEX(SCurve!$P$67:$BK$67,A14) -> 0.50819328 | F14: =IF(ISNUMBER(D14),D14-E14,"") | G14: =IF(ISNUMBER(D14),IF(E14=0,"",D14/E14),"") | H14: =IF(NOT(ISNUMBER(G14)),"",IF(G14>=$K$4,"Hijau",IF(G14>=$L$4,"Kuning","Merah")))
A15: 8 | B15: =INDEX(SCurve!$P$16:$BK$16,A15) -> 46199 | C15: =INDEX(SCurve!$P$17:$BK$17,A15) -> 46205 | E15: =INDEX(SCurve!$P$67:$BK$67,A15) -> 0.60588235 | F15: =IF(ISNUMBER(D15),D15-E15,"") | G15: =IF(ISNUMBER(D15),IF(E15=0,"",D15/E15),"") | H15: =IF(NOT(ISNUMBER(G15)),"",IF(G15>=$K$4,"Hijau",IF(G15>=$L$4,"Kuning","Merah")))
A16: 9 | B16: =INDEX(SCurve!$P$16:$BK$16,A16) -> 46206 | C16: =INDEX(SCurve!$P$17:$BK$17,A16) -> 46212 | E16: =INDEX(SCurve!$P$67:$BK$67,A16) -> 0.65 | F16: =IF(ISNUMBER(D16),D16-E16,"") | G16: =IF(ISNUMBER(D16),IF(E16=0,"",D16/E16),"") | H16: =IF(NOT(ISNUMBER(G16)),"",IF(G16>=$K$4,"Hijau",IF(G16>=$L$4,"Kuning","Merah")))
A17: 10 | B17: =INDEX(SCurve!$P$16:$BK$16,A17) -> 46213 | C17: =INDEX(SCurve!$P$17:$BK$17,A17) -> 46219 | E17: =INDEX(SCurve!$P$67:$BK$67,A17) -> 0.77 | F17: =IF(ISNUMBER(D17),D17-E17,"") | G17: =IF(ISNUMBER(D17),IF(E17=0,"",D17/E17),"") | H17: =IF(NOT(ISNUMBER(G17)),"",IF(G17>=$K$4,"Hijau",IF(G17>=$L$4,"Kuning","Merah")))
A18: 11 | B18: =INDEX(SCurve!$P$16:$BK$16,A18) -> 46220 | C18: =INDEX(SCurve!$P$17:$BK$17,A18) -> 46226 | E18: =INDEX(SCurve!$P$67:$BK$67,A18) -> 0.7925 | F18: =IF(ISNUMBER(D18),D18-E18,"") | G18: =IF(ISNUMBER(D18),IF(E18=0,"",D18/E18),"") | H18: =IF(NOT(ISNUMBER(G18)),"",IF(G18>=$K$4,"Hijau",IF(G18>=$L$4,"Kuning","Merah")))
A19: 12 | B19: =INDEX(SCurve!$P$16:$BK$16,A19) -> 46227 | C19: =INDEX(SCurve!$P$17:$BK$17,A19) -> 46233 | E19: =INDEX(SCurve!$P$67:$BK$67,A19) -> 0.81333333 | F19: =IF(ISNUMBER(D19),D19-E19,"") | G19: =IF(ISNUMBER(D19),IF(E19=0,"",D19/E19),"") | H19: =IF(NOT(ISNUMBER(G19)),"",IF(G19>=$K$4,"Hijau",IF(G19>=$L$4,"Kuning","Merah")))
A20: 13 | B20: =INDEX(SCurve!$P$16:$BK$16,A20) -> 46234 | C20: =INDEX(SCurve!$P$17:$BK$17,A20) -> 46240 | E20: =INDEX(SCurve!$P$67:$BK$67,A20) -> 0.84 | F20: =IF(ISNUMBER(D20),D20-E20,"") | G20: =IF(ISNUMBER(D20),IF(E20=0,"",D20/E20),"") | H20: =IF(NOT(ISNUMBER(G20)),"",IF(G20>=$K$4,"Hijau",IF(G20>=$L$4,"Kuning","Merah")))
... A55: 48 | B55: =INDEX(SCurve!$P$16:$BK$16,A55) -> 46479 | C55: =INDEX(SCurve!$P$17:$BK$17,A55) -> 46485 | E55: =INDEX(SCurve!$P$67:$BK$67,A55) -> 1 | F55: =IF(ISNUMBER(D55),D55-E55,"") | G55: =IF(ISNUMBER(D55),IF(E55=0,"",D55/E55),"") | H55: =IF(NOT(ISNUMBER(G55)),"",IF(G55>=$K$4,"Hijau",IF(G55>=$L$4,"Kuning","Merah")))

Sheet Catatan Perbaikan
A1: Catatan Perbaikan v2
A3: # | B3: Perbaikan | C3: Lokasi | D3: Sebelum → Sesudah
A4: 1 | B4: Hapus ROUNDUP pada angka inti | C4: SCurve!B11, C11, C62, J62, L62, M62, O62, P62 | D4: Target W1 6,00% → 5,14%; actual 6% → 5,5%; deviasi 0 → +0,4 pp
A5: 2 | B5: Baris TOTAL hanya menjumlah baris task; Go Live (baris 60) kini ikut | C5: SCurve!P62:BK62 | D5: Target kumulatif berhenti 99,78% → 100%
A6: 3 | B6: Satu kalender libur (named range Hari_Libur = Libur!A2:A200) dipakai di semua formula | C6: SCurve kolom H, I, dan P:BK (task) | D6: Sebelumnya A2:A38 (mingguan), A2:A56 (durasi), tanpa libur (kolom I)
A7: 4 | B7: Subtotal fase PREPARATION menunjuk baris yang benar | C7: SCurve!J24:M24 | D7: Sebelumnya merujuk baris 28 & 32
A8: 5 | B8: % progress fase = bobot-tertimbang (L ÷ C); Linear Target fase = J ÷ C | C8: SCurve kolom I, K baris fase | D8: Sebelumnya campuran AVERAGE/SUM (bisa >100%)
A9: 6 | B9: Formula mingguan pada baris fase dihapus; tanggal fase = MIN/MAX tanggal anak | C9: SCurve baris 20,24,28,32,38,43,51,56 | D9: Mencegah hitung ganda saat jadwal bergeser; fase REQUIREMENT kini mulai 11 Mei
A10: 7 | B10: Linear Target task: perbaiki off-by-one (status date = hari mulai dihitung) | C10: SCurve kolom I | D10: Task 1 hari kini dihitung penuh pada tanggal tersebut
A11: 8 | B11: Sheet Log_Mingguan: histori Actual per minggu, SPI, RAG, kontrol model | C11: Sheet Log_Mingguan | D11: Baris 68 SCurve kini terhubung ke log; deviasi minggu belum berjalan kosong
A12: 9 | B12: Chart dibuat ulang (Week 1–20, memakai data log, sel kosong = gap) | C12: SCurve (area O73:Y104) | D12: Sebelumnya berhenti di Week-16 sehingga Go Live tidak tampil
A13: 10 | B13: Validasi input 0–100% pada kolom K task; label kolom bantu F/G/N/O; penomoran Go Live = IX; hapus sel nyasar | C13: SCurve | D13: —
B15: Belum diubah (di luar ruang lingkup)
B16: Sheet milestone progress (7 sel error referensi putus, data proyek lama – sudah error sejak file asli), Sheet2, Info Mingguan, SCurve D1, tabel GAP SCurve!B74:E111, daftar Libur (ada tanggal 2025 & duplikat 1 Jan 2026) | D16: Disarankan dirapikan/dihapus setelah Anda konfirmasi
B17: Bobot task, WBS (Documentation/Training/BAST belum ada), P16/P17 (minggu-1 = 8 hari) dan Status Date C8 tetap input manual | D17: Perlu keputusan PM/tim

Sheet milestone progress
A1: No | B1: Task | C1: Bobot | D1: Start Date | E1: Finish Date | H1: Duration | I1: Linear Target | J1: Linear Target | K1: Actual Progress | L1: Actual Progress | M1: Deviation
A2: I | B2: Initiation & Analysis | C2: 0.02 | D2: 46034 | E2: 46034 | H2: 1 | J2: 1 | L2: =SCurve!K20 -> 1 | M2: =L2-J2 -> 0
A3: II | B3: Requirement, Analisa & Desain | C3: 0.15 | D3: 46035 | E3: 46049 | H3: 11 | J3: 1 | L3: =SCurve!#REF! -> #REF! | M3: =L3-J3 -> #REF!
A4: II | B4: DevOps & CMS Setup | C4: 0.1 | D4: 46034 | E4: 46045 | H4: 10 | J4: 1 | L4: =SCurve!#REF! -> #REF! | M4: =L4-J4 -> #REF!
A5: III | B5: Project Implementation | C5: 0.36 | D5: 46051 | E5: 46140 | F5: 0.13 | G5: 0.13 | H5: 64 | I5: 0 | J5: =SCurve!I24 -> 0.5 | L5: =SCurve!K24 -> 0.5 | M5: =L5-J5 -> 0
A6: IV | B6: Testing & UAT | C6: 0.18 | D6: 46066 | E6: 46077 | F6: 0.14 | G6: 0.14 | H6: 8 | I6: 0 | J6: 0 | L6: =SCurve!K56 -> 0 | M6: =L6-J6 -> 0
A7: V | B7: Pentest | C7: 0.03 | D7: 46150 | E7: 46184 | H7: 25 | J7: 0 | L7: 0
A8: VI | B8: Training | C8: 0.04 | D8: 46185 | E8: 46190 | H8: 4 | J8: 0 | L8: =SCurve!#REF! -> #REF!
A9: VII | B9: Go Live Preparation | C9: 0.08 | D9: 46185 | E9: 46197 | H9: 9 | J9: 0 | L9: =SCurve!#REF! -> #REF!
A10: VIII | B10: Go Live | C10: 0.04 | D10: 46198 | E10: 46198 | H10: 1 | J10: 0 | L10: =SCurve!#REF! -> #REF!
B17: Total | J17: =SCurve!J62 -> 0.051428571 | L17: =SCurve!L62 -> 0.055

Sheet Sheet2
G16: Task Name | H16: Start | I16: Finish
G17: Initiation & Planning | H17: 46149 | I17: 11/05/2026
G18: Preparation | H18: 12/05/2026 | I18: 19/05/2026
G19: Requirement | H19: 12/05/2026 | I19: 26/05/2026
G20: Analysis & Design | H20: 29/05/2026 | I20: 11/06/2026
G21: Development | H21: 12/06/2026 | I21: 16/07/2026
G22: Core Feature development | H22: 12/06/2026 | I22: 02/07/2026
G23: Integration (Guci & Ossera) | H23: 26/06/2026 | I23: 09/07/2026
G24: Bug Fixing & Code Review | H24: 10/07/2026 | I24: 16/07/2026
G25: Testing | H25: 17/07/2026 | I25: 11/08/2026
G26: SAST DAST | H26: 13/08/2026 | I26: 20/08/2026
G27: Deploy | H27: 21/08/2026 | I27: 27/08/2026
G28: Go Live | H28: 28/08/2026 | I28: 28/08/2026
G29: Documentation | H29: 29/05/2026 | I29: 31/08/2026

Sheet Libur
A1: Tanggal Libur
A2: 45658
A3: 45684
A4: 45685
A5: 45686
A6: 45744
A7: 45745
A8: 45747
A9: 45748
A10: 45749
A11: 45750
A12: 45751
A13: 45754
... A31: 46023
A32: 46023 | B32: Kamis | C32: Tahun Baru 2026 Masehi
A33: 46038 | B33: Jumat | C33: Isra Mikraj Nabi Muhammad SAW
A34: 46070 | B34: Selasa | C34: Tahun Baru Imlek 2577 Kongzili
A35: 46100 | B35: Kamis | C35: Hari Suci Nyepi Tahun Baru Saka 1948
A36: 46102 | B36: Sabtu | C36: Hari Raya Idul Fitri 1447 Hijriah (*)
A37: 46103 | B37: Minggu | C37: Hari Raya Idul Fitri 1447 Hijriah (*)
A38: 46115 | B38: Jumat | C38: Wafat Yesus Kristus
A39: 46117 | B39: Minggu | C39: Kebangkitan Yesus Kristus (Paskah)
A40: 46143 | B40: Jumat | C40: Hari Buruh Internasional
A41: 46156 | B41: Kamis | C41: Kenaikan Yesus Kristus
A42: 46169 | B42: Rabu | C42: Hari Raya Idul Adha 1447 Hijriah (*)
A43: 46173 | B43: Minggu | C43: Hari Raya Waisak 2570 BE
... A56: 46380 | B56: Kamis | C56: Hari Raya Natal

Sheet Info Mingguan
A1: Minggu Ke | B1: Tanggal Awal | C1: Tanggal Akhir
A2: M1 | B2: 45656 | C2: 45662
A3: M2 | B3: 45663 | C3: 45669
A4: M3 | B4: 45670 | C4: 45676
A5: M4 | B5: 45677 | C5: 45683
A6: M5 | B6: 45684 | C6: 45690
A7: M6 | B7: 45691 | C7: 45697
A8: M7 | B8: 45698 | C8: 45704
A9: M8 | B9: 45705 | C9: 45711
A10: M9 | B10: 45712 | C10: 45718
A11: M10 | B11: 45719 | C11: 45725
A12: M11 | B12: 45726 | C12: 45732
A13: M12 | B13: 45733 | C13: 45739
... A53: M52 | B53: 46013 | C53: 46019

Sheet SCurve D1
B2: Project Name | C2: Auto Bandwidth on Demand
B3: Client | C3: PT Aplikanusa Lintasarta
B4: Project Manager | C4: Lesy Nugraheny
B5: Project Due Date | C5: 46262
B6: PO Due Date | C6: 46265
B7: W1 Project Date | C7: 46156
B8: Project Status Date | C8: 46150
B10: Target Linear | C10: Progress | D10: Deviation
B11: =ROUNDUP(J62,2) -> 0.01 | C11: =ROUNDUP(L62,3) -> 0.01 | D11: =C11-B11 -> 0
P16: 46149 | Q16: =P17+1 -> 46151 | R16: =Q17+1 -> 46158 | S16: =R17+1 -> 46165 | T16: =S17+1 -> 46172 | U16: =T17+1 -> 46179 | V16: =U17+1 -> 46186 | W16: =V17+1 -> 46193 | X16: =W17+1 -> 46200 | ... BK16: =BJ17+1 -> 46473
P17: 46150 | Q17: =P17+7 -> 46157 | R17: =Q17+7 -> 46164 | S17: =R17+7 -> 46171 | T17: =S17+7 -> 46178 | U17: =T17+7 -> 46185 | V17: =U17+7 -> 46192 | W17: =V17+7 -> 46199 | X17: =W17+7 -> 46206 | ... BK17: =BJ17+7 -> 46479
A18: No | B18: Task | C18: Bobot | D18: Start Date | E18: Finish Date | H18: Duration | I18: Linear Target | K18: Actual Progress | M18: Deviation | P18: Week-01 | Q18: Week-02 | R18: Week-03 | S18: Week-04 | T18: Week-05 | U18: Week-06 | V18: Week-07 | W18: Week-08 | X18: Week-09 | Y18: Week-10 | Z18: Week-11 | AA18: Week-12 | AB18: Week-13 | AC18: Week-14 | AD18: Week-15 | AE18: Week-16 | AF18: Week-17 | AG18: Week-18 | AH18: Week-19 | AI18: Week-20 | AJ18: Week-21 | AK18: Week-22 | AL18: Week-23 | AM18: Week-24 | AN18: Week-25 | AO18: Week-26 | AP18: Week-27 | AQ18: Week-28 | AR18: Week-29 | AS18: Week-30 | AT18: Week-31 | AU18: Week-32 | AV18: Week-33 | AW18: Week-34 | AX18: Week-35 | AY18: Week-36 | AZ18: Week-37 | BA18: Week-38 | BB18: Week-39 | BC18: Week-40 | BD18: Week-41 | BE18: Week-42 | BF18: Week-43 | BG18: Week-44 | BH18: Week-45 | BI18: Week-46 | BJ18: Week-47 | BK18: Week-48
I19: Weight (%) | J19: % | K19: Progress | L19: % | M19: %
A20: I | B20: INITIATION & PLANNING | C20: =SUM(C21:C21) -> 0.01 | D20: 46149 | E20: 46149 | H20: =NETWORKDAYS(D20,E20,Libur!$A$2:$A$56) -> 1 | I20: =IF($C$8>E20,100/100,IF($C$8<=D20,0,(NETWORKDAYS(D20,$C$8)/NETWORKDAYS(D20,E20)))) -> 1 | J20: =SUM(J21:J21) -> 0.01 | K20: =AVERAGE(K21:K21) -> 1 | L20: =SUM(L21:L21) -> 0.01 | M20: =SUM(M21:M21) -> 0
B21: Kick Off Meeting | C21: 0.01 | D21: 46149 | E21: 46149 | F21: =C21 -> 0.01 | G21: =SUM(P21:AZ21) -> 0.01 | H21: =NETWORKDAYS(D21,E21,Libur!$A$2:$A$56) -> 1 | I21: =IF($C$8>E21,100/100,IF($C$8<=D21,0,(NETWORKDAYS(D21,$C$8)/NETWORKDAYS(D21,E21)))) -> 1 | J21: =I21*F21 -> 0.01 | K21: 1 | L21: =C21*K21 -> 0.01 | M21: =L21-J21 -> 0 | N21: =C21 -> 0.01 | O21: =SUM(P21:BK21) -> 0.01 | P21: =IF(AND($D21<=P$17,$E21>=P$16),$C21*NETWORKDAYS(MAX($D21,P$16),MIN($E21,P$17),Libur!$A$2:$A$38)/NETWORKDAYS($D21,$E21,Libur!$A$2:$A$38),0) -> 0.01 | Q21: =IF(AND($D21<=Q$17,$E21>=Q$16),$C21*NETWORKDAYS(MAX($D21,Q$16),MIN($E21,Q$17),Libur!$A$2:$A$38)/NETWORKDAYS($D21,$E21,Libur!$A$2:$A$38),0) -> 0 | R21: =IF(AND($D21<=R$17,$E21>=R$16),$C21*NETWORKDAYS(MAX($D21,R$16),MIN($E21,R$17),Libur!$A$2:$A$38)/NETWORKDAYS($D21,$E21,Libur!$A$2:$A$38),0) -> 0 | S21: =IF(AND($D21<=S$17,$E21>=S$16),$C21*NETWORKDAYS(MAX($D21,S$16),MIN($E21,S$17),Libur!$A$2:$A$38)/NETWORKDAYS($D21,$E21,Libur!$A$2:$A$38),0) -> 0 | T21: =IF(AND($D21<=T$17,$E21>=T$16),$C21*NETWORKDAYS(MAX($D21,T$16),MIN($E21,T$17),Libur!$A$2:$A$38)/NETWORKDAYS($D21,$E21,Libur!$A$2:$A$38),0) -> 0 | U21: =IF(AND($D21<=U$17,$E21>=U$16),$C21*NETWORKDAYS(MAX($D21,U$16),MIN($E21,U$17),Libur!$A$2:$A$38)/NETWORKDAYS($D21,$E21,Libur!$A$2:$A$38),0) -> 0 | V21: =IF(AND($D21<=V$17,$E21>=V$16),$C21*NETWORKDAYS(MAX($D21,V$16),MIN($E21,V$17),Libur!$A$2:$A$38)/NETWORKDAYS($D21,$E21,Libur!$A$2:$A$38),0) -> 0 | W21: =IF(AND($D21<=W$17,$E21>=W$16),$C21*NETWORKDAYS(MAX($D21,W$16),MIN($E21,W$17),Libur!$A$2:$A$38)/NETWORKDAYS($D21,$E21,Libur!$A$2:$A$38),0) -> 0 | ... BK21: =IF(AND($D21<=BK$17,$E21>=BK$16),$C21*NETWORKDAYS(MAX($D21,BK$16),MIN($E21,BK$17),Libur!$A$2:$A$38)/NETWORKDAYS($D21,$E21,Libur!$A$2:$A$38),0) -> 0
P22: =IF(AND($D22<=P$17,$E22>=P$16),$C22*NETWORKDAYS(MAX($D22,P$16),MIN($E22,P$17),Libur!$A$2:$A$38)/NETWORKDAYS($D22,$E22,Libur!$A$2:$A$38),0) -> 0 | Q22: =IF(AND($D22<=Q$17,$E22>=Q$16),$C22*NETWORKDAYS(MAX($D22,Q$16),MIN($E22,Q$17),Libur!$A$2:$A$38)/NETWORKDAYS($D22,$E22,Libur!$A$2:$A$38),0) -> 0 | R22: =IF(AND($D22<=R$17,$E22>=R$16),$C22*NETWORKDAYS(MAX($D22,R$16),MIN($E22,R$17),Libur!$A$2:$A$38)/NETWORKDAYS($D22,$E22,Libur!$A$2:$A$38),0) -> 0 | S22: =IF(AND($D22<=S$17,$E22>=S$16),$C22*NETWORKDAYS(MAX($D22,S$16),MIN($E22,S$17),Libur!$A$2:$A$38)/NETWORKDAYS($D22,$E22,Libur!$A$2:$A$38),0) -> 0 | T22: =IF(AND($D22<=T$17,$E22>=T$16),$C22*NETWORKDAYS(MAX($D22,T$16),MIN($E22,T$17),Libur!$A$2:$A$38)/NETWORKDAYS($D22,$E22,Libur!$A$2:$A$38),0) -> 0 | U22: =IF(AND($D22<=U$17,$E22>=U$16),$C22*NETWORKDAYS(MAX($D22,U$16),MIN($E22,U$17),Libur!$A$2:$A$38)/NETWORKDAYS($D22,$E22,Libur!$A$2:$A$38),0) -> 0 | V22: =IF(AND($D22<=V$17,$E22>=V$16),$C22*NETWORKDAYS(MAX($D22,V$16),MIN($E22,V$17),Libur!$A$2:$A$38)/NETWORKDAYS($D22,$E22,Libur!$A$2:$A$38),0) -> 0 | W22: =IF(AND($D22<=W$17,$E22>=W$16),$C22*NETWORKDAYS(MAX($D22,W$16),MIN($E22,W$17),Libur!$A$2:$A$38)/NETWORKDAYS($D22,$E22,Libur!$A$2:$A$38),0) -> 0 | ... BK22: =IF(AND($D22<=BK$17,$E22>=BK$16),$C22*NETWORKDAYS(MAX($D22,BK$16),MIN($E22,BK$17),Libur!$A$2:$A$38)/NETWORKDAYS($D22,$E22,Libur!$A$2:$A$38),0) -> 0
P23: =IF(AND($D23<=P$17,$E23>=P$16),$C23*NETWORKDAYS(MAX($D23,P$16),MIN($E23,P$17),Libur!$A$2:$A$38)/NETWORKDAYS($D23,$E23,Libur!$A$2:$A$38),0) -> 0 | Q23: =IF(AND($D23<=Q$17,$E23>=Q$16),$C23*NETWORKDAYS(MAX($D23,Q$16),MIN($E23,Q$17),Libur!$A$2:$A$38)/NETWORKDAYS($D23,$E23,Libur!$A$2:$A$38),0) -> 0 | R23: =IF(AND($D23<=R$17,$E23>=R$16),$C23*NETWORKDAYS(MAX($D23,R$16),MIN($E23,R$17),Libur!$A$2:$A$38)/NETWORKDAYS($D23,$E23,Libur!$A$2:$A$38),0) -> 0 | S23: =IF(AND($D23<=S$17,$E23>=S$16),$C23*NETWORKDAYS(MAX($D23,S$16),MIN($E23,S$17),Libur!$A$2:$A$38)/NETWORKDAYS($D23,$E23,Libur!$A$2:$A$38),0) -> 0 | T23: =IF(AND($D23<=T$17,$E23>=T$16),$C23*NETWORKDAYS(MAX($D23,T$16),MIN($E23,T$17),Libur!$A$2:$A$38)/NETWORKDAYS($D23,$E23,Libur!$A$2:$A$38),0) -> 0 | U23: =IF(AND($D23<=U$17,$E23>=U$16),$C23*NETWORKDAYS(MAX($D23,U$16),MIN($E23,U$17),Libur!$A$2:$A$38)/NETWORKDAYS($D23,$E23,Libur!$A$2:$A$38),0) -> 0 | V23: =IF(AND($D23<=V$17,$E23>=V$16),$C23*NETWORKDAYS(MAX($D23,V$16),MIN($E23,V$17),Libur!$A$2:$A$38)/NETWORKDAYS($D23,$E23,Libur!$A$2:$A$38),0) -> 0 | W23: =IF(AND($D23<=W$17,$E23>=W$16),$C23*NETWORKDAYS(MAX($D23,W$16),MIN($E23,W$17),Libur!$A$2:$A$38)/NETWORKDAYS($D23,$E23,Libur!$A$2:$A$38),0) -> 0 | ... BK23: =IF(AND($D23<=BK$17,$E23>=BK$16),$C23*NETWORKDAYS(MAX($D23,BK$16),MIN($E23,BK$17),Libur!$A$2:$A$38)/NETWORKDAYS($D23,$E23,Libur!$A$2:$A$38),0) -> 0
A24: II | B24: PREPARATION | C24: =SUM(C25:C26) -> 0.04 | D24: 46151 | E24: 46161 | H24: =NETWORKDAYS(D24,E24,Libur!$A$2:$A$56) -> 5 | I24: =IF($C$8>E24,100/100,IF($C$8<=D24,0,(NETWORKDAYS(D24,$C$8)/NETWORKDAYS(D24,E24)))) -> 0 | J24: =SUM(J28:J28,J32) -> 0 | K24: =SUM(K28:K28,K32) -> 0 | L24: =SUM(L28:L28,L32) -> 0 | M24: =SUM(M28:M28,M32) -> 0 | R24: =IF(AND($D24<=R$17,$E24>=R$16),$C24*NETWORKDAYS(MAX($D24,R$16),MIN($E24,R$17),Libur!$A$2:$A$38)/NETWORKDAYS($D24,$E24,Libur!$A$2:$A$38),0) -> 0.011428571 | S24: =IF(AND($D24<=S$17,$E24>=S$16),$C24*NETWORKDAYS(MAX($D24,S$16),MIN($E24,S$17),Libur!$A$2:$A$38)/NETWORKDAYS($D24,$E24,Libur!$A$2:$A$38),0) -> 0 | T24: =IF(AND($D24<=T$17,$E24>=T$16),$C24*NETWORKDAYS(MAX($D24,T$16),MIN($E24,T$17),Libur!$A$2:$A$38)/NETWORKDAYS($D24,$E24,Libur!$A$2:$A$38),0) -> 0 | U24: =IF(AND($D24<=U$17,$E24>=U$16),$C24*NETWORKDAYS(MAX($D24,U$16),MIN($E24,U$17),Libur!$A$2:$A$38)/NETWORKDAYS($D24,$E24,Libur!$A$2:$A$38),0) -> 0 | V24: =IF(AND($D24<=V$17,$E24>=V$16),$C24*NETWORKDAYS(MAX($D24,V$16),MIN($E24,V$17),Libur!$A$2:$A$38)/NETWORKDAYS($D24,$E24,Libur!$A$2:$A$38),0) -> 0 | W24: =IF(AND($D24<=W$17,$E24>=W$16),$C24*NETWORKDAYS(MAX($D24,W$16),MIN($E24,W$17),Libur!$A$2:$A$38)/NETWORKDAYS($D24,$E24,Libur!$A$2:$A$38),0) -> 0 | X24: =IF(AND($D24<=X$17,$E24>=X$16),$C24*NETWORKDAYS(MAX($D24,X$16),MIN($E24,X$17),Libur!$A$2:$A$38)/NETWORKDAYS($D24,$E24,Libur!$A$2:$A$38),0) -> 0 | Y24: =IF(AND($D24<=Y$17,$E24>=Y$16),$C24*NETWORKDAYS(MAX($D24,Y$16),MIN($E24,Y$17),Libur!$A$2:$A$38)/NETWORKDAYS($D24,$E24,Libur!$A$2:$A$38),0) -> 0 | ... BK24: =IF(AND($D24<=BK$17,$E24>=BK$16),$C24*NETWORKDAYS(MAX($D24,BK$16),MIN($E24,BK$17),Libur!$A$2:$A$38)/NETWORKDAYS($D24,$E24,Libur!$A$2:$A$38),0) -> 0
B25: Sync Repo with the Staging Repo | C25: 0.02 | D25: 46151 | E25: 46155 | F25: =C25 -> 0.02 | G25: =SUM(P25:AZ25) -> 0.02 | H25: =NETWORKDAYS(D25,E25,Libur!$A$2:$A$56) -> 3 | I25: =IF($C$8>E25,100/100,IF($C$8<=D25,0,(NETWORKDAYS(D25,$C$8)/NETWORKDAYS(D25,E25)))) -> 0 | J25: =I25*F25 -> 0 | K25: 0 | L25: =C25*K25 -> 0 | M25: =L25-J25 -> 0 | N25: =C25 -> 0.02 | O25: =SUM(P25:BK25) -> 0.02 | P25: =IF(AND($D25<=P$17,$E25>=P$16),$C25*NETWORKDAYS(MAX($D25,P$16),MIN($E25,P$17),Libur!$A$2:$A$38)/NETWORKDAYS($D25,$E25,Libur!$A$2:$A$38),0) -> 0 | Q25: =IF(AND($D25<=Q$17,$E25>=Q$16),$C25*NETWORKDAYS(MAX($D25,Q$16),MIN($E25,Q$17),Libur!$A$2:$A$38)/NETWORKDAYS($D25,$E25,Libur!$A$2:$A$38),0) -> 0.02 | R25: =IF(AND($D25<=R$17,$E25>=R$16),$C25*NETWORKDAYS(MAX($D25,R$16),MIN($E25,R$17),Libur!$A$2:$A$38)/NETWORKDAYS($D25,$E25,Libur!$A$2:$A$38),0) -> 0 | S25: =IF(AND($D25<=S$17,$E25>=S$16),$C25*NETWORKDAYS(MAX($D25,S$16),MIN($E25,S$17),Libur!$A$2:$A$38)/NETWORKDAYS($D25,$E25,Libur!$A$2:$A$38),0) -> 0 | T25: =IF(AND($D25<=T$17,$E25>=T$16),$C25*NETWORKDAYS(MAX($D25,T$16),MIN($E25,T$17),Libur!$A$2:$A$38)/NETWORKDAYS($D25,$E25,Libur!$A$2:$A$38),0) -> 0 | U25: =IF(AND($D25<=U$17,$E25>=U$16),$C25*NETWORKDAYS(MAX($D25,U$16),MIN($E25,U$17),Libur!$A$2:$A$38)/NETWORKDAYS($D25,$E25,Libur!$A$2:$A$38),0) -> 0 | V25: =IF(AND($D25<=V$17,$E25>=V$16),$C25*NETWORKDAYS(MAX($D25,V$16),MIN($E25,V$17),Libur!$A$2:$A$38)/NETWORKDAYS($D25,$E25,Libur!$A$2:$A$38),0) -> 0 | W25: =IF(AND($D25<=W$17,$E25>=W$16),$C25*NETWORKDAYS(MAX($D25,W$16),MIN($E25,W$17),Libur!$A$2:$A$38)/NETWORKDAYS($D25,$E25,Libur!$A$2:$A$38),0) -> 0 | ... BK25: =IF(AND($D25<=BK$17,$E25>=BK$16),$C25*NETWORKDAYS(MAX($D25,BK$16),MIN($E25,BK$17),Libur!$A$2:$A$38)/NETWORKDAYS($D25,$E25,Libur!$A$2:$A$38),0) -> 0
